<?xml version="1.0" encoding="utf-8"?>
<!-- This URDF was automatically created by SolidWorks to URDF Exporter! Originally created by Stephen Brawner (brawner@gmail.com) 
     Commit Version: 1.5.1-0-g916b5db  Build Version: 1.5.7152.31018
     For more information, please see http://wiki.ros.org/sw_urdf_exporter -->
<robot
  name="FirstTry0314">
  <link
    name="base_link">
    <inertial>
      <origin
        xyz="-0.008197 -0.0073304 0.1"
        rpy="0 0 0" />
      <mass
        value="1.3313" />
      <inertia
        ixx="0.020645"
        ixy="-3.7461E-19"
        ixz="-2.6999E-20"
        iyy="0.023213"
        iyz="1.2187E-18"
        izz="0.0034844" />
    </inertial>
    <visual>
      <origin
        xyz="0 0 0"
        rpy="0 0 0" />
      <geometry>
        <mesh
          filename="package://FirstTry0314/meshes/base_link.STL" />
      </geometry>
      <material
        name="mat">
        <color
          rgba="1 1 1 1" />
      </material>
    </visual>
    <collision>
      <origin
        xyz="0 0 0"
        rpy="0 0 0" />
      <geometry>
        <mesh
          filename="package://FirstTry0314/meshes/base_link.STL" />
      </geometry>
    </collision>
  </link>
  <link
    name="Link-11">
    <inertial>
      <origin
        xyz="0.00052443 -0.048741 5.5511E-17"
        rpy="0 0 0" />
      <mass
        value="0.13426" />
      <inertia
        ixx="5.9611E-05"
        ixy="8.862E-08"
        ixz="-1.2705E-21"
        iyy="5.5476E-05"
        iyz="-8.8508E-22"
        izz="6.1772E-05" />
    </inertial>
    <visual>
      <origin
        xyz="0 0 0"
        rpy="0 0 0" />
      <geometry>
        <mesh
          filename="package://FirstTry0314/meshes/Link-11.STL" />
      </geometry>
      <material
        name="mat">
        <color
          rgba="1 1 1 1" />
      </material>
    </visual>
    <collision>
      <origin
        xyz="0 0 0"
        rpy="0 0 0" />
      <geometry>
        <mesh
          filename="package://FirstTry0314/meshes/Link-11.STL" />
      </geometry>
    </collision>
  </link>
  <joint
    name="Joint-11"
    type="continuous">
    <origin
      xyz="0.091803 -0.25 0.012279"
      rpy="0 -1.5303 1.5708" />
    <parent
      link="base_link" />
    <child
      link="Link-11" />
    <axis
      xyz="0 1 0" />
  </joint>
  <link
    name="Link-12">
    <inertial>
      <origin
        xyz="-0.0057876 -0.036825 0.0040114"
        rpy="0 0 0" />
      <mass
        value="0.12291" />
      <inertia
        ixx="7.6838E-05"
        ixy="-4.075E-07"
        ixz="1.327E-05"
        iyy="7.1867E-05"
        iyz="2.8244E-07"
        izz="4.7075E-05" />
    </inertial>
    <visual>
      <origin
        xyz="0 0 0"
        rpy="0 0 0" />
      <geometry>
        <mesh
          filename="package://FirstTry0314/meshes/Link-12.STL" />
      </geometry>
      <material
        name="mat">
        <color
          rgba="1 1 1 1" />
      </material>
    </visual>
    <collision>
      <origin
        xyz="0 0 0"
        rpy="0 0 0" />
      <geometry>
        <mesh
          filename="package://FirstTry0314/meshes/Link-12.STL" />
      </geometry>
    </collision>
  </link>
  <joint
    name="Joint-12"
    type="continuous">
    <origin
      xyz="0.037602 -0.05 0"
      rpy="0 -1.4921 1.5708" />
    <parent
      link="Link-11" />
    <child
      link="Link-12" />
    <axis
      xyz="0 1 0" />
  </joint>
  <link
    name="Link-13">
    <inertial>
      <origin
        xyz="8.3267E-17 0.1 0.0028666"
        rpy="0 0 0" />
      <mass
        value="0.49632" />
      <inertia
        ixx="0.0019227"
        ixy="-1.2535E-18"
        ixz="2.7105E-20"
        iyy="0.00020011"
        iyz="-5.7725E-19"
        izz="0.0019242" />
    </inertial>
    <visual>
      <origin
        xyz="0 0 0"
        rpy="0 0 0" />
      <geometry>
        <mesh
          filename="package://FirstTry0314/meshes/Link-13.STL" />
      </geometry>
      <material
        name="mat">
        <color
          rgba="1 1 1 1" />
      </material>
    </visual>
    <collision>
      <origin
        xyz="0 0 0"
        rpy="0 0 0" />
      <geometry>
        <mesh
          filename="package://FirstTry0314/meshes/Link-13.STL" />
      </geometry>
    </collision>
  </link>
  <joint
    name="Joint-13"
    type="continuous">
    <origin
      xyz="0 -0.037398 0.025"
      rpy="1.5708 -1.328 1.5708" />
    <parent
      link="Link-12" />
    <child
      link="Link-13" />
    <axis
      xyz="0 0 1" />
  </joint>
  <link
    name="Link-14">
    <inertial>
      <origin
        xyz="0.047942 0.21275 0.00053964"
        rpy="0 0 0" />
      <mass
        value="1.3182" />
      <inertia
        ixx="0.028713"
        ixy="-0.00057712"
        ixz="3.2444E-05"
        iyy="0.00066838"
        iyz="0.00015134"
        izz="0.028833" />
    </inertial>
    <visual>
      <origin
        xyz="0 0 0"
        rpy="0 0 0" />
      <geometry>
        <mesh
          filename="package://FirstTry0314/meshes/Link-14.STL" />
      </geometry>
      <material
        name="mat">
        <color
          rgba="1 1 1 1" />
      </material>
    </visual>
    <collision>
      <origin
        xyz="0 0 0"
        rpy="0 0 0" />
      <geometry>
        <mesh
          filename="package://FirstTry0314/meshes/Link-14.STL" />
      </geometry>
    </collision>
  </link>
  <joint
    name="Joint-14"
    type="continuous">
    <origin
      xyz="0 0.2 0"
      rpy="-3.1416 0 0.65082" />
    <parent
      link="Link-13" />
    <child
      link="Link-14" />
    <axis
      xyz="0 0 1" />
  </joint>
  <link
    name="Link-21">
    <inertial>
      <origin
        xyz="0.00052443 -0.048741 -5.5511E-17"
        rpy="0 0 0" />
      <mass
        value="0.13426" />
      <inertia
        ixx="5.9611E-05"
        ixy="8.862E-08"
        ixz="1.6941E-21"
        iyy="5.5476E-05"
        iyz="1.4029E-21"
        izz="6.1772E-05" />
    </inertial>
    <visual>
      <origin
        xyz="0 0 0"
        rpy="0 0 0" />
      <geometry>
        <mesh
          filename="package://FirstTry0314/meshes/Link-21.STL" />
      </geometry>
      <material
        name="mat">
        <color
          rgba="1 1 1 1" />
      </material>
    </visual>
    <collision>
      <origin
        xyz="0 0 0"
        rpy="0 0 0" />
      <geometry>
        <mesh
          filename="package://FirstTry0314/meshes/Link-21.STL" />
      </geometry>
    </collision>
  </link>
  <joint
    name="Joint-21"
    type="continuous">
    <origin
      xyz="-0.1082 -0.25 0.012279"
      rpy="3.1416 -1.4554 1.5708" />
    <parent
      link="base_link" />
    <child
      link="Link-21" />
    <axis
      xyz="0 1 0" />
  </joint>
  <link
    name="Link-22">
    <inertial>
      <origin
        xyz="-0.0057876 -0.036099 0.0040114"
        rpy="0 0 0" />
      <mass
        value="0.12291" />
      <inertia
        ixx="7.6838E-05"
        ixy="-4.075E-07"
        ixz="1.327E-05"
        iyy="7.1867E-05"
        iyz="2.8244E-07"
        izz="4.7075E-05" />
    </inertial>
    <visual>
      <origin
        xyz="0 0 0"
        rpy="0 0 0" />
      <geometry>
        <mesh
          filename="package://FirstTry0314/meshes/Link-22.STL" />
      </geometry>
      <material
        name="mat">
        <color
          rgba="1 1 1 1" />
      </material>
    </visual>
    <collision>
      <origin
        xyz="0 0 0"
        rpy="0 0 0" />
      <geometry>
        <mesh
          filename="package://FirstTry0314/meshes/Link-22.STL" />
      </geometry>
    </collision>
  </link>
  <joint
    name="Joint-22"
    type="continuous">
    <origin
      xyz="0.038328 -0.05 0"
      rpy="-3.1416 -1.5334 -1.5708" />
    <parent
      link="Link-21" />
    <child
      link="Link-22" />
    <axis
      xyz="0 1 0" />
  </joint>
  <link
    name="Link-23">
    <inertial>
      <origin
        xyz="-8.3267E-17 0.1 0.0028666"
        rpy="0 0 0" />
      <mass
        value="0.49632" />
      <inertia
        ixx="0.0019227"
        ixy="1.527E-18"
        ixz="-2.7105E-20"
        iyy="0.00020011"
        iyz="1.6348E-18"
        izz="0.0019242" />
    </inertial>
    <visual>
      <origin
        xyz="0 0 0"
        rpy="0 0 0" />
      <geometry>
        <mesh
          filename="package://FirstTry0314/meshes/Link-23.STL" />
      </geometry>
      <material
        name="mat">
        <color
          rgba="1 1 1 1" />
      </material>
    </visual>
    <collision>
      <origin
        xyz="0 0 0"
        rpy="0 0 0" />
      <geometry>
        <mesh
          filename="package://FirstTry0314/meshes/Link-23.STL" />
      </geometry>
    </collision>
  </link>
  <joint
    name="Joint-23"
    type="continuous">
    <origin
      xyz="0 -0.036672 0.025"
      rpy="1.5708 -1.3017 1.5708" />
    <parent
      link="Link-22" />
    <child
      link="Link-23" />
    <axis
      xyz="0 0 1" />
  </joint>
  <link
    name="Link-24">
    <inertial>
      <origin
        xyz="0.047942 0.21275 0.00053964"
        rpy="0 0 0" />
      <mass
        value="1.3182" />
      <inertia
        ixx="0.028713"
        ixy="-0.00057712"
        ixz="3.2444E-05"
        iyy="0.00066838"
        iyz="0.00015134"
        izz="0.028833" />
    </inertial>
    <visual>
      <origin
        xyz="0 0 0"
        rpy="0 0 0" />
      <geometry>
        <mesh
          filename="package://FirstTry0314/meshes/Link-24.STL" />
      </geometry>
      <material
        name="mat">
        <color
          rgba="1 1 1 1" />
      </material>
    </visual>
    <collision>
      <origin
        xyz="0 0 0"
        rpy="0 0 0" />
      <geometry>
        <mesh
          filename="package://FirstTry0314/meshes/Link-24.STL" />
      </geometry>
    </collision>
  </link>
  <joint
    name="Joint-24"
    type="continuous">
    <origin
      xyz="0 0.2 0"
      rpy="3.1416 0 0.52071" />
    <parent
      link="Link-23" />
    <child
      link="Link-24" />
    <axis
      xyz="0 0 1" />
  </joint>
  <link
    name="Link-31">
    <inertial>
      <origin
        xyz="0.00052443 -0.048741 -1.3878E-17"
        rpy="0 0 0" />
      <mass
        value="0.13426" />
      <inertia
        ixx="5.9611E-05"
        ixy="8.862E-08"
        ixz="-5.294E-21"
        iyy="5.5476E-05"
        iyz="2.3868E-21"
        izz="6.1772E-05" />
    </inertial>
    <visual>
      <origin
        xyz="0 0 0"
        rpy="0 0 0" />
      <geometry>
        <mesh
          filename="package://FirstTry0314/meshes/Link-31.STL" />
      </geometry>
      <material
        name="mat">
        <color
          rgba="1 1 1 1" />
      </material>
    </visual>
    <collision>
      <origin
        xyz="0 0 0"
        rpy="0 0 0" />
      <geometry>
        <mesh
          filename="package://FirstTry0314/meshes/Link-31.STL" />
      </geometry>
    </collision>
  </link>
  <joint
    name="Joint-31"
    type="continuous">
    <origin
      xyz="0.091803 0.05 0.012279"
      rpy="0 -1.5303 1.5708" />
    <parent
      link="base_link" />
    <child
      link="Link-31" />
    <axis
      xyz="0 1 0" />
  </joint>
  <link
    name="Link-32">
    <inertial>
      <origin
        xyz="-0.0057876 -0.036825 0.0040114"
        rpy="0 0 0" />
      <mass
        value="0.12291" />
      <inertia
        ixx="7.6838E-05"
        ixy="-4.075E-07"
        ixz="1.327E-05"
        iyy="7.1867E-05"
        iyz="2.8244E-07"
        izz="4.7075E-05" />
    </inertial>
    <visual>
      <origin
        xyz="0 0 0"
        rpy="0 0 0" />
      <geometry>
        <mesh
          filename="package://FirstTry0314/meshes/Link-32.STL" />
      </geometry>
      <material
        name="mat">
        <color
          rgba="1 1 1 1" />
      </material>
    </visual>
    <collision>
      <origin
        xyz="0 0 0"
        rpy="0 0 0" />
      <geometry>
        <mesh
          filename="package://FirstTry0314/meshes/Link-32.STL" />
      </geometry>
    </collision>
  </link>
  <joint
    name="Joint-32"
    type="continuous">
    <origin
      xyz="0.037602 -0.05 0"
      rpy="0 -1.4921 1.5708" />
    <parent
      link="Link-31" />
    <child
      link="Link-32" />
    <axis
      xyz="0 1 0" />
  </joint>
  <link
    name="Link-33">
    <inertial>
      <origin
        xyz="8.3267E-17 0.1 0.0028666"
        rpy="0 0 0" />
      <mass
        value="0.49632" />
      <inertia
        ixx="0.0019227"
        ixy="-1.9327E-18"
        ixz="5.421E-20"
        iyy="0.00020011"
        iyz="-2.8376E-19"
        izz="0.0019242" />
    </inertial>
    <visual>
      <origin
        xyz="0 0 0"
        rpy="0 0 0" />
      <geometry>
        <mesh
          filename="package://FirstTry0314/meshes/Link-33.STL" />
      </geometry>
      <material
        name="mat">
        <color
          rgba="1 1 1 1" />
      </material>
    </visual>
    <collision>
      <origin
        xyz="0 0 0"
        rpy="0 0 0" />
      <geometry>
        <mesh
          filename="package://FirstTry0314/meshes/Link-33.STL" />
      </geometry>
    </collision>
  </link>
  <joint
    name="Joint-33"
    type="continuous">
    <origin
      xyz="0 -0.037398 0.025"
      rpy="1.5708 -1.3019 1.5708" />
    <parent
      link="Link-32" />
    <child
      link="Link-33" />
    <axis
      xyz="0 0 1" />
  </joint>
  <link
    name="Link-34">
    <inertial>
      <origin
        xyz="0.047942 0.21275 0.00053964"
        rpy="0 0 0" />
      <mass
        value="1.3182" />
      <inertia
        ixx="0.028713"
        ixy="-0.00057712"
        ixz="3.2444E-05"
        iyy="0.00066838"
        iyz="0.00015134"
        izz="0.028833" />
    </inertial>
    <visual>
      <origin
        xyz="0 0 0"
        rpy="0 0 0" />
      <geometry>
        <mesh
          filename="package://FirstTry0314/meshes/Link-34.STL" />
      </geometry>
      <material
        name="mat">
        <color
          rgba="1 1 1 1" />
      </material>
    </visual>
    <collision>
      <origin
        xyz="0 0 0"
        rpy="0 0 0" />
      <geometry>
        <mesh
          filename="package://FirstTry0314/meshes/Link-34.STL" />
      </geometry>
    </collision>
  </link>
  <joint
    name="Joint-34"
    type="continuous">
    <origin
      xyz="0 0.2 0"
      rpy="-3.1416 0 0.38436" />
    <parent
      link="Link-33" />
    <child
      link="Link-34" />
    <axis
      xyz="0 0 1" />
  </joint>
  <link
    name="Link-41">
    <inertial>
      <origin
        xyz="0.00052443 -0.048741 6.9389E-18"
        rpy="0 0 0" />
      <mass
        value="0.13426" />
      <inertia
        ixx="5.9611E-05"
        ixy="8.862E-08"
        ixz="0"
        iyy="5.5476E-05"
        iyz="1.4261E-21"
        izz="6.1772E-05" />
    </inertial>
    <visual>
      <origin
        xyz="0 0 0"
        rpy="0 0 0" />
      <geometry>
        <mesh
          filename="package://FirstTry0314/meshes/Link-41.STL" />
      </geometry>
      <material
        name="mat">
        <color
          rgba="1 1 1 1" />
      </material>
    </visual>
    <collision>
      <origin
        xyz="0 0 0"
        rpy="0 0 0" />
      <geometry>
        <mesh
          filename="package://FirstTry0314/meshes/Link-41.STL" />
      </geometry>
    </collision>
  </link>
  <joint
    name="Joint-41"
    type="continuous">
    <origin
      xyz="-0.1082 0.05 0.012279"
      rpy="3.1416 -1.4451 1.5708" />
    <parent
      link="base_link" />
    <child
      link="Link-41" />
    <axis
      xyz="0 1 0" />
  </joint>
  <link
    name="Link-42">
    <inertial>
      <origin
        xyz="-0.0057876 -0.035945 0.0040114"
        rpy="0 0 0" />
      <mass
        value="0.12291" />
      <inertia
        ixx="7.6838E-05"
        ixy="-4.075E-07"
        ixz="1.327E-05"
        iyy="7.1867E-05"
        iyz="2.8244E-07"
        izz="4.7075E-05" />
    </inertial>
    <visual>
      <origin
        xyz="0 0 0"
        rpy="0 0 0" />
      <geometry>
        <mesh
          filename="package://FirstTry0314/meshes/Link-42.STL" />
      </geometry>
      <material
        name="mat">
        <color
          rgba="1 1 1 1" />
      </material>
    </visual>
    <collision>
      <origin
        xyz="0 0 0"
        rpy="0 0 0" />
      <geometry>
        <mesh
          filename="package://FirstTry0314/meshes/Link-42.STL" />
      </geometry>
    </collision>
  </link>
  <joint
    name="Joint-42"
    type="continuous">
    <origin
      xyz="0.038483 -0.05 0"
      rpy="3.1416 -1.5334 -1.5708" />
    <parent
      link="Link-41" />
    <child
      link="Link-42" />
    <axis
      xyz="0 1 0" />
  </joint>
  <link
    name="Link-43">
    <inertial>
      <origin
        xyz="-5.5511E-17 0.1 0.0028666"
        rpy="0 0 0" />
      <mass
        value="0.49632" />
      <inertia
        ixx="0.0019227"
        ixy="1.3239E-18"
        ixz="2.7105E-20"
        iyy="0.00020011"
        iyz="-4.3707E-19"
        izz="0.0019242" />
    </inertial>
    <visual>
      <origin
        xyz="0 0 0"
        rpy="0 0 0" />
      <geometry>
        <mesh
          filename="package://FirstTry0314/meshes/Link-43.STL" />
      </geometry>
      <material
        name="mat">
        <color
          rgba="1 1 1 1" />
      </material>
    </visual>
    <collision>
      <origin
        xyz="0 0 0"
        rpy="0 0 0" />
      <geometry>
        <mesh
          filename="package://FirstTry0314/meshes/Link-43.STL" />
      </geometry>
    </collision>
  </link>
  <joint
    name="Joint-43"
    type="continuous">
    <origin
      xyz="0 -0.036517 0.025"
      rpy="1.5708 -1.3498 1.5708" />
    <parent
      link="Link-42" />
    <child
      link="Link-43" />
    <axis
      xyz="0 0 1" />
  </joint>
  <link
    name="Link-44">
    <inertial>
      <origin
        xyz="0.047942 0.21275 0.00053964"
        rpy="0 0 0" />
      <mass
        value="1.3182" />
      <inertia
        ixx="0.028713"
        ixy="-0.00057712"
        ixz="3.2444E-05"
        iyy="0.00066838"
        iyz="0.00015134"
        izz="0.028833" />
    </inertial>
    <visual>
      <origin
        xyz="0 0 0"
        rpy="0 0 0" />
      <geometry>
        <mesh
          filename="package://FirstTry0314/meshes/Link-44.STL" />
      </geometry>
      <material
        name="mat">
        <color
          rgba="1 1 1 1" />
      </material>
    </visual>
    <collision>
      <origin
        xyz="0 0 0"
        rpy="0 0 0" />
      <geometry>
        <mesh
          filename="package://FirstTry0314/meshes/Link-44.STL" />
      </geometry>
    </collision>
  </link>
  <joint
    name="Joint-44"
    type="continuous">
    <origin
      xyz="0 0.2 0"
      rpy="-3.1416 0 0.47223" />
    <parent
      link="Link-43" />
    <child
      link="Link-44" />
    <axis
      xyz="0 0 1" />
  </joint>
</robot>