<?xml version="1.0" encoding="utf-8"?>
<!-- This URDF was automatically created by SolidWorks to URDF Exporter! Originally created by Stephen Brawner (brawner@gmail.com) 
     Commit Version: 1.5.1-0-g916b5db  Build Version: 1.5.7152.31018
     For more information, please see http://wiki.ros.org/sw_urdf_exporter -->
<robot
  name="Severus">
  <link
    name="base_link">
    <inertial>
      <origin
        xyz="0 0.00254950495049505 6.93889390390723E-18"
        rpy="0 0 0" />
      <mass
        value="0.089240866316035" />
      <inertia
        ixx="0.000124472658151784"
        ixy="0"
        ixz="0"
        iyy="0.000248529738126238"
        iyz="-4.13590306276514E-22"
        izz="0.000124472658151784" />
    </inertial>
    <visual>
      <origin
        xyz="0 0 0"
        rpy="0 0 0" />
      <geometry>
        <mesh
          filename="package://Severus/meshes/base_link.STL" />
      </geometry>
      <material
        name="">
        <color
          rgba="0.792156862745098 0.819607843137255 0.933333333333333 1" />
      </material>
    </visual>
    <collision>
      <origin
        xyz="0 0 0"
        rpy="0 0 0" />
      <geometry>
        <mesh
          filename="package://Severus/meshes/base_link.STL" />
      </geometry>
    </collision>
  </link>
  <link
    name="Link_11">
    <inertial>
      <origin
        xyz="-0.00544885570783534 0.0207646350841081 -8.06800064006279E-19"
        rpy="0 0 0" />
      <mass
        value="0.0196850105367549" />
      <inertia
        ixx="4.09990655058184E-06"
        ixy="5.68717463137068E-07"
        ixz="3.82004647330432E-24"
        iyy="2.16121564980124E-06"
        iyz="-3.37216020632057E-22"
        izz="3.6148599812894E-06" />
    </inertial>
    <visual>
      <origin
        xyz="0 0 0"
        rpy="0 0 0" />
      <geometry>
        <mesh
          filename="package://Severus/meshes/Link_11.STL" />
      </geometry>
      <material
        name="">
        <color
          rgba="0.792156862745098 0.819607843137255 0.933333333333333 1" />
      </material>
    </visual>
    <collision>
      <origin
        xyz="0 0 0"
        rpy="0 0 0" />
      <geometry>
        <mesh
          filename="package://Severus/meshes/Link_11.STL" />
      </geometry>
    </collision>
  </link>
  <joint
    name="Joint_11"
    type="continuous">
    <origin
      xyz="0 0 0.01"
      rpy="1.5708 0 0" />
    <parent
      link="base_link" />
    <child
      link="Link_11" />
    <axis
      xyz="0 1 0" />
  </joint>
  <link
    name="Link_12">
    <inertial>
      <origin
        xyz="0.00235471782377051 0.102740932943639 -0.00686923988626232"
        rpy="0 0 0" />
      <mass
        value="0.0911028752058656" />
      <inertia
        ixx="0.000411099958915835"
        ixy="3.38393768266908E-06"
        ixz="2.39495619668546E-06"
        iyy="3.25991345832866E-05"
        iyz="4.20131038837999E-05"
        izz="0.00039869764677922" />
    </inertial>
    <visual>
      <origin
        xyz="0 0 0"
        rpy="0 0 0" />
      <geometry>
        <mesh
          filename="package://Severus/meshes/Link_12.STL" />
      </geometry>
      <material
        name="">
        <color
          rgba="0.792156862745098 0.819607843137255 0.933333333333333 1" />
      </material>
    </visual>
    <collision>
      <origin
        xyz="0 0 0"
        rpy="0 0 0" />
      <geometry>
        <mesh
          filename="package://Severus/meshes/Link_12.STL" />
      </geometry>
    </collision>
  </link>
  <joint
    name="Joint_12"
    type="continuous">
    <origin
      xyz="0 0.03 0"
      rpy="0 0 0" />
    <parent
      link="Link_11" />
    <child
      link="Link_12" />
    <axis
      xyz="1 0 0" />
  </joint>
  <link
    name="Link_13">
    <inertial>
      <origin
        xyz="-0.00291458130465664 -0.085 -6.93889390390723E-18"
        rpy="0 0 0" />
      <mass
        value="0.0736028752058656" />
      <inertia
        ixx="0.000274223596823039"
        ixy="9.7609573942794E-21"
        ixz="3.2792743371176E-21"
        iyy="1.32163868307615E-05"
        iyz="-1.40620704134015E-20"
        izz="0.00027679716019314" />
    </inertial>
    <visual>
      <origin
        xyz="0 0 0"
        rpy="0 0 0" />
      <geometry>
        <mesh
          filename="package://Severus/meshes/Link_13.STL" />
      </geometry>
      <material
        name="">
        <color
          rgba="0.792156862745098 0.819607843137255 0.933333333333333 1" />
      </material>
    </visual>
    <collision>
      <origin
        xyz="0 0 0"
        rpy="0 0 0" />
      <geometry>
        <mesh
          filename="package://Severus/meshes/Link_13.STL" />
      </geometry>
    </collision>
  </link>
  <joint
    name="Joint_13"
    type="continuous">
    <origin
      xyz="0 0.17 -0.04"
      rpy="3.1416 0 0" />
    <parent
      link="Link_12" />
    <child
      link="Link_13" />
    <axis
      xyz="1 0 0" />
  </joint>
  <link
    name="Link_14">
    <inertial>
      <origin
        xyz="0.000960612583321093 -0.0282365920434951 -6.93889390390723E-18"
        rpy="0 0 0" />
      <mass
        value="0.111658730985146" />
      <inertia
        ixx="0.000137584245329062"
        ixy="-2.60680394422135E-06"
        ixz="1.13991510372147E-23"
        iyy="0.000251797665265952"
        iyz="-4.0271986878171E-21"
        izz="0.00013758061122721" />
    </inertial>
    <visual>
      <origin
        xyz="0 0 0"
        rpy="0 0 0" />
      <geometry>
        <mesh
          filename="package://Severus/meshes/Link_14.STL" />
      </geometry>
      <material
        name="">
        <color
          rgba="0.792156862745098 0.819607843137255 0.933333333333333 1" />
      </material>
    </visual>
    <collision>
      <origin
        xyz="0 0 0"
        rpy="0 0 0" />
      <geometry>
        <mesh
          filename="package://Severus/meshes/Link_14.STL" />
      </geometry>
    </collision>
  </link>
  <joint
    name="Joint_14"
    type="continuous">
    <origin
      xyz="0 -0.17 0"
      rpy="0 0 0" />
    <parent
      link="Link_13" />
    <child
      link="Link_14" />
    <axis
      xyz="1 0 0" />
  </joint>
</robot>