#VRML_SIM R2023b utf8
# license: Apache License 2.0
# license url: http://www.apache.org/licenses/LICENSE-2.0
# This is a proto file for Webots for the FirstTry0314
# Extracted from: C:/Users/andyf/PycharmProjects/Pytorch_with_webots/protos/robots/FirstTry0314/urdf/FirstTry0314.urdf

PROTO FirstTry0314 [
  field  SFVec3f     translation     0 0 0
  field  SFRotation  rotation        0 0 1 0
  field  SFString    name            "FirstTry0314"  # Is `Robot.name`.
  field  SFString    controller      "void"          # Is `Robot.controller`.
  field  MFString    controllerArgs  []              # Is `Robot.controllerArgs`.
  field  SFString    customData      ""              # Is `Robot.customData`.
  field  SFBool      supervisor      FALSE           # Is `Robot.supervisor`.
  field  SFBool      synchronization TRUE            # Is `Robot.synchronization`.
  field  SFBool      selfCollision   FALSE           # Is `Robot.selfCollision`.
]
{
  Robot {
    translation IS translation
    rotation IS rotation
    controller IS controller
    controllerArgs IS controllerArgs
    customData IS customData
    supervisor IS supervisor
    synchronization IS synchronization
    selfCollision IS selfCollision
    children [
      Shape {
        appearance DEF mat PBRAppearance {
          roughness 1.000000
          metalness 0
        }
        geometry DEF base_link Mesh {
          url "C:/Users/andyf/PycharmProjects/Pytorch_with_webots/protos/robots/FirstTry0314/meshes/base_link.STL"
        }
      }
      HingeJoint {
        jointParameters HingeJointParameters {
          axis -1.000000 -0.000004 0.000000
          anchor 0.091803 -0.250000 0.012279
        }
        device [
          RotationalMotor {
            name "Joint-11"
            maxTorque 10000
          }
          PositionSensor {
            name "Joint-11_sensor"
          }
        ]
        endPoint Solid {
          translation 0.091803 -0.250000 0.012279
          rotation 0.569398 -0.569396 0.592937 2.071177
          children [
            Shape {
              appearance USE mat
              geometry DEF Link-11 Mesh {
                url "C:/Users/andyf/PycharmProjects/Pytorch_with_webots/protos/robots/FirstTry0314/meshes/Link-11.STL"
              }
            }
            HingeJoint {
              jointParameters HingeJointParameters {
                axis -1.000000 -0.000004 -0.000000
                anchor 0.037602 -0.050000 0.000000
              }
              device [
                RotationalMotor {
                  name "Joint-12"
                  maxTorque 10000
                }
                PositionSensor {
                  name "Joint-12_sensor"
                }
              ]
              endPoint Solid {
                translation 0.037602 -0.050000 0.000000
                rotation 0.561599 -0.561597 0.607630 2.049574
                children [
                  Shape {
                    appearance USE mat
                    geometry DEF Link-12 Mesh {
                      url "C:/Users/andyf/PycharmProjects/Pytorch_with_webots/protos/robots/FirstTry0314/meshes/Link-12.STL"
                    }
                  }
                  HingeJoint {
                    jointParameters HingeJointParameters {
                      axis 1.000000 0.000007 -0.000001
                      anchor 0.000000 -0.037398 0.025000
                    }
                    device [
                      RotationalMotor {
                        name "Joint-13"
                        maxTorque 10000
                      }
                      PositionSensor {
                        name "Joint-13_sensor"
                      }
                    ]
                    endPoint Solid {
                      translation 0.000000 -0.037398 0.025000
                      rotation 0.704490 0.085949 0.704490 2.970126
                      children [
                        Shape {
                          appearance USE mat
                          geometry DEF Link-13 Mesh {
                            url "C:/Users/andyf/PycharmProjects/Pytorch_with_webots/protos/robots/FirstTry0314/meshes/Link-13.STL"
                          }
                        }
                        HingeJoint {
                          jointParameters HingeJointParameters {
                            axis 0.000004 -0.000006 -1.000000
                            anchor 0.000000 0.200000 0.000000
                          }
                          device [
                            RotationalMotor {
                              name "Joint-14"
                              maxTorque 10000
                            }
                            PositionSensor {
                              name "Joint-14_sensor"
                            }
                          ]
                          endPoint Solid {
                            translation 0.000000 0.200000 0.000000
                            rotation -0.947520 -0.319697 -0.000001 3.141600
                            children [
                              Shape {
                                appearance USE mat
                                geometry DEF Link-14 Mesh {
                                  url "C:/Users/andyf/PycharmProjects/Pytorch_with_webots/protos/robots/FirstTry0314/meshes/Link-14.STL"
                                }
                              }
                            ]
                            name "Link-14"
                            boundingObject USE Link-14
                            physics Physics {
                              density -1
                              mass 1.318200
                              centerOfMass [ 0.047942 0.212750 0.000540 ]
                              inertiaMatrix [
                                2.871300e-02 6.683800e-04 2.883300e-02
                                -5.771200e-04 3.244400e-05 1.513400e-04
                              ]
                            }
                          }
                        }
                      ]
                      name "Link-13"
                      boundingObject USE Link-13
                      physics Physics {
                        density -1
                        mass 0.496320
                        centerOfMass [ 0.000000 0.100000 0.002867 ]
                        inertiaMatrix [
                          1.922700e-03 2.001100e-04 1.924200e-03
                          -1.253500e-18 2.710500e-20 -5.772500e-19
                        ]
                      }
                    }
                  }
                ]
                name "Link-12"
                boundingObject USE Link-12
                physics Physics {
                  density -1
                  mass 0.122910
                  centerOfMass [ -0.005788 -0.036825 0.004011 ]
                  inertiaMatrix [
                    7.683800e-05 7.186700e-05 4.707500e-05
                    -4.075000e-07 1.327000e-05 2.824400e-07
                  ]
                }
              }
            }
          ]
          name "Link-11"
          boundingObject USE Link-11
          physics Physics {
            density -1
            mass 0.134260
            centerOfMass [ 0.000524 -0.048741 0.000000 ]
            inertiaMatrix [
              5.961100e-05 5.547600e-05 6.177200e-05
              8.862000e-08 -1.270500e-21 -8.850800e-22
            ]
          }
        }
      }
      HingeJoint {
        jointParameters HingeJointParameters {
          axis 1.000000 0.000011 -0.000001
          anchor -0.108200 -0.250000 0.012279
        }
        device [
          RotationalMotor {
            name "Joint-21"
            maxTorque 10000
          }
          PositionSensor {
            name "Joint-21_sensor"
          }
        ]
        endPoint Solid {
          translation -0.108200 -0.250000 0.012279
          rotation 0.598308 0.598314 0.532962 4.120939
          children [
            Shape {
              appearance USE mat
              geometry DEF Link-21 Mesh {
                url "C:/Users/andyf/PycharmProjects/Pytorch_with_webots/protos/robots/FirstTry0314/meshes/Link-21.STL"
              }
            }
            HingeJoint {
              jointParameters HingeJointParameters {
                axis -1.000000 0.000011 0.000000
                anchor 0.038328 -0.050000 0.000000
              }
              device [
                RotationalMotor {
                  name "Joint-22"
                  maxTorque 10000
                }
                PositionSensor {
                  name "Joint-22_sensor"
                }
              ]
              endPoint Solid {
                translation 0.038328 -0.050000 0.000000
                rotation -0.584412 0.584418 -0.562955 4.167073
                children [
                  Shape {
                    appearance USE mat
                    geometry DEF Link-22 Mesh {
                      url "C:/Users/andyf/PycharmProjects/Pytorch_with_webots/protos/robots/FirstTry0314/meshes/Link-22.STL"
                    }
                  }
                  HingeJoint {
                    jointParameters HingeJointParameters {
                      axis 1.000000 0.000007 -0.000001
                      anchor 0.000000 -0.036672 0.025000
                    }
                    device [
                      RotationalMotor {
                        name "Joint-23"
                        maxTorque 10000
                      }
                      PositionSensor {
                        name "Joint-23_sensor"
                      }
                    ]
                    endPoint Solid {
                      translation 0.000000 -0.036672 0.025000
                      rotation 0.703889 0.095285 0.703889 2.951606
                      children [
                        Shape {
                          appearance USE mat
                          geometry DEF Link-23 Mesh {
                            url "C:/Users/andyf/PycharmProjects/Pytorch_with_webots/protos/robots/FirstTry0314/meshes/Link-23.STL"
                          }
                        }
                        HingeJoint {
                          jointParameters HingeJointParameters {
                            axis -0.000004 0.000006 -1.000000
                            anchor 0.000000 0.200000 0.000000
                          }
                          device [
                            RotationalMotor {
                              name "Joint-24"
                              maxTorque 10000
                            }
                            PositionSensor {
                              name "Joint-24_sensor"
                            }
                          ]
                          endPoint Solid {
                            translation 0.000000 0.200000 0.000000
                            rotation 0.966299 0.257424 -0.000001 3.141600
                            children [
                              Shape {
                                appearance USE mat
                                geometry DEF Link-24 Mesh {
                                  url "C:/Users/andyf/PycharmProjects/Pytorch_with_webots/protos/robots/FirstTry0314/meshes/Link-24.STL"
                                }
                              }
                            ]
                            name "Link-24"
                            boundingObject USE Link-24
                            physics Physics {
                              density -1
                              mass 1.318200
                              centerOfMass [ 0.047942 0.212750 0.000540 ]
                              inertiaMatrix [
                                2.871300e-02 6.683800e-04 2.883300e-02
                                -5.771200e-04 3.244400e-05 1.513400e-04
                              ]
                            }
                          }
                        }
                      ]
                      name "Link-23"
                      boundingObject USE Link-23
                      physics Physics {
                        density -1
                        mass 0.496320
                        centerOfMass [ -0.000000 0.100000 0.002867 ]
                        inertiaMatrix [
                          1.922700e-03 2.001100e-04 1.924200e-03
                          1.527000e-18 -2.710500e-20 1.634800e-18
                        ]
                      }
                    }
                  }
                ]
                name "Link-22"
                boundingObject USE Link-22
                physics Physics {
                  density -1
                  mass 0.122910
                  centerOfMass [ -0.005788 -0.036099 0.004011 ]
                  inertiaMatrix [
                    7.683800e-05 7.186700e-05 4.707500e-05
                    -4.075000e-07 1.327000e-05 2.824400e-07
                  ]
                }
              }
            }
          ]
          name "Link-21"
          boundingObject USE Link-21
          physics Physics {
            density -1
            mass 0.134260
            centerOfMass [ 0.000524 -0.048741 -0.000000 ]
            inertiaMatrix [
              5.961100e-05 5.547600e-05 6.177200e-05
              8.862000e-08 1.694100e-21 1.402900e-21
            ]
          }
        }
      }
      HingeJoint {
        jointParameters HingeJointParameters {
          axis -1.000000 -0.000004 0.000000
          anchor 0.091803 0.050000 0.012279
        }
        device [
          RotationalMotor {
            name "Joint-31"
            maxTorque 10000
          }
          PositionSensor {
            name "Joint-31_sensor"
          }
        ]
        endPoint Solid {
          translation 0.091803 0.050000 0.012279
          rotation 0.569398 -0.569396 0.592937 2.071177
          children [
            Shape {
              appearance USE mat
              geometry DEF Link-31 Mesh {
                url "C:/Users/andyf/PycharmProjects/Pytorch_with_webots/protos/robots/FirstTry0314/meshes/Link-31.STL"
              }
            }
            HingeJoint {
              jointParameters HingeJointParameters {
                axis -1.000000 -0.000004 -0.000000
                anchor 0.037602 -0.050000 0.000000
              }
              device [
                RotationalMotor {
                  name "Joint-32"
                  maxTorque 10000
                }
                PositionSensor {
                  name "Joint-32_sensor"
                }
              ]
              endPoint Solid {
                translation 0.037602 -0.050000 0.000000
                rotation 0.561599 -0.561597 0.607630 2.049574
                children [
                  Shape {
                    appearance USE mat
                    geometry DEF Link-32 Mesh {
                      url "C:/Users/andyf/PycharmProjects/Pytorch_with_webots/protos/robots/FirstTry0314/meshes/Link-32.STL"
                    }
                  }
                  HingeJoint {
                    jointParameters HingeJointParameters {
                      axis 1.000000 0.000007 -0.000001
                      anchor 0.000000 -0.037398 0.025000
                    }
                    device [
                      RotationalMotor {
                        name "Joint-33"
                        maxTorque 10000
                      }
                      PositionSensor {
                        name "Joint-33_sensor"
                      }
                    ]
                    endPoint Solid {
                      translation 0.000000 -0.037398 0.025000
                      rotation 0.703894 0.095214 0.703894 2.951747
                      children [
                        Shape {
                          appearance USE mat
                          geometry DEF Link-33 Mesh {
                            url "C:/Users/andyf/PycharmProjects/Pytorch_with_webots/protos/robots/FirstTry0314/meshes/Link-33.STL"
                          }
                        }
                        HingeJoint {
                          jointParameters HingeJointParameters {
                            axis 0.000003 -0.000007 -1.000000
                            anchor 0.000000 0.200000 0.000000
                          }
                          device [
                            RotationalMotor {
                              name "Joint-34"
                              maxTorque 10000
                            }
                            PositionSensor {
                              name "Joint-34_sensor"
                            }
                          ]
                          endPoint Solid {
                            translation 0.000000 0.200000 0.000000
                            rotation -0.981590 -0.190999 -0.000001 3.141600
                            children [
                              Shape {
                                appearance USE mat
                                geometry DEF Link-34 Mesh {
                                  url "C:/Users/andyf/PycharmProjects/Pytorch_with_webots/protos/robots/FirstTry0314/meshes/Link-34.STL"
                                }
                              }
                            ]
                            name "Link-34"
                            boundingObject USE Link-34
                            physics Physics {
                              density -1
                              mass 1.318200
                              centerOfMass [ 0.047942 0.212750 0.000540 ]
                              inertiaMatrix [
                                2.871300e-02 6.683800e-04 2.883300e-02
                                -5.771200e-04 3.244400e-05 1.513400e-04
                              ]
                            }
                          }
                        }
                      ]
                      name "Link-33"
                      boundingObject USE Link-33
                      physics Physics {
                        density -1
                        mass 0.496320
                        centerOfMass [ 0.000000 0.100000 0.002867 ]
                        inertiaMatrix [
                          1.922700e-03 2.001100e-04 1.924200e-03
                          -1.932700e-18 5.421000e-20 -2.837600e-19
                        ]
                      }
                    }
                  }
                ]
                name "Link-32"
                boundingObject USE Link-32
                physics Physics {
                  density -1
                  mass 0.122910
                  centerOfMass [ -0.005788 -0.036825 0.004011 ]
                  inertiaMatrix [
                    7.683800e-05 7.186700e-05 4.707500e-05
                    -4.075000e-07 1.327000e-05 2.824400e-07
                  ]
                }
              }
            }
          ]
          name "Link-31"
          boundingObject USE Link-31
          physics Physics {
            density -1
            mass 0.134260
            centerOfMass [ 0.000524 -0.048741 -0.000000 ]
            inertiaMatrix [
              5.961100e-05 5.547600e-05 6.177200e-05
              8.862000e-08 -5.294000e-21 2.386800e-21
            ]
          }
        }
      }
      HingeJoint {
        jointParameters HingeJointParameters {
          axis 1.000000 0.000011 -0.000001
          anchor -0.108200 0.050000 0.012279
        }
        device [
          RotationalMotor {
            name "Joint-41"
            maxTorque 10000
          }
          PositionSensor {
            name "Joint-41_sensor"
          }
        ]
        endPoint Solid {
          translation -0.108200 0.050000 0.012279
          rotation 0.600060 0.600066 0.529006 4.114768
          children [
            Shape {
              appearance USE mat
              geometry DEF Link-41 Mesh {
                url "C:/Users/andyf/PycharmProjects/Pytorch_with_webots/protos/robots/FirstTry0314/meshes/Link-41.STL"
              }
            }
            HingeJoint {
              jointParameters HingeJointParameters {
                axis -1.000000 -0.000004 -0.000000
                anchor 0.038483 -0.050000 0.000000
              }
              device [
                RotationalMotor {
                  name "Joint-42"
                  maxTorque 10000
                }
                PositionSensor {
                  name "Joint-42_sensor"
                }
              ]
              endPoint Solid {
                translation 0.038483 -0.050000 0.000000
                rotation 0.584414 -0.584412 0.562958 2.116121
                children [
                  Shape {
                    appearance USE mat
                    geometry DEF Link-42 Mesh {
                      url "C:/Users/andyf/PycharmProjects/Pytorch_with_webots/protos/robots/FirstTry0314/meshes/Link-42.STL"
                    }
                  }
                  HingeJoint {
                    jointParameters HingeJointParameters {
                      axis 1.000000 0.000007 -0.000001
                      anchor 0.000000 -0.036517 0.025000
                    }
                    device [
                      RotationalMotor {
                        name "Joint-43"
                        maxTorque 10000
                      }
                      PositionSensor {
                        name "Joint-43_sensor"
                      }
                    ]
                    endPoint Solid {
                      translation 0.000000 -0.036517 0.025000
                      rotation 0.704941 0.078216 0.704941 2.985489
                      children [
                        Shape {
                          appearance USE mat
                          geometry DEF Link-43 Mesh {
                            url "C:/Users/andyf/PycharmProjects/Pytorch_with_webots/protos/robots/FirstTry0314/meshes/Link-43.STL"
                          }
                        }
                        HingeJoint {
                          jointParameters HingeJointParameters {
                            axis 0.000003 -0.000007 -1.000000
                            anchor 0.000000 0.200000 0.000000
                          }
                          device [
                            RotationalMotor {
                              name "Joint-44"
                              maxTorque 10000
                            }
                            PositionSensor {
                              name "Joint-44_sensor"
                            }
                          ]
                          endPoint Solid {
                            translation 0.000000 0.200000 0.000000
                            rotation -0.972254 -0.233927 -0.000001 3.141600
                            children [
                              Shape {
                                appearance USE mat
                                geometry DEF Link-44 Mesh {
                                  url "C:/Users/andyf/PycharmProjects/Pytorch_with_webots/protos/robots/FirstTry0314/meshes/Link-44.STL"
                                }
                              }
                            ]
                            name "Link-44"
                            boundingObject USE Link-44
                            physics Physics {
                              density -1
                              mass 1.318200
                              centerOfMass [ 0.047942 0.212750 0.000540 ]
                              inertiaMatrix [
                                2.871300e-02 6.683800e-04 2.883300e-02
                                -5.771200e-04 3.244400e-05 1.513400e-04
                              ]
                            }
                          }
                        }
                      ]
                      name "Link-43"
                      boundingObject USE Link-43
                      physics Physics {
                        density -1
                        mass 0.496320
                        centerOfMass [ -0.000000 0.100000 0.002867 ]
                        inertiaMatrix [
                          1.922700e-03 2.001100e-04 1.924200e-03
                          1.323900e-18 2.710500e-20 -4.370700e-19
                        ]
                      }
                    }
                  }
                ]
                name "Link-42"
                boundingObject USE Link-42
                physics Physics {
                  density -1
                  mass 0.122910
                  centerOfMass [ -0.005788 -0.035945 0.004011 ]
                  inertiaMatrix [
                    7.683800e-05 7.186700e-05 4.707500e-05
                    -4.075000e-07 1.327000e-05 2.824400e-07
                  ]
                }
              }
            }
          ]
          name "Link-41"
          boundingObject USE Link-41
          physics Physics {
            density -1
            mass 0.134260
            centerOfMass [ 0.000524 -0.048741 0.000000 ]
            inertiaMatrix [
              5.961100e-05 5.547600e-05 6.177200e-05
              8.862000e-08 0.000000e+00 1.426100e-21
            ]
          }
        }
      }
    ]
    name IS name
    boundingObject USE base_link
    physics Physics {
      density -1
      mass 1.331300
      centerOfMass [ -0.008197 -0.007330 0.100000 ]
      inertiaMatrix [
        2.064500e-02 2.321300e-02 3.484400e-03
        -3.746100e-19 -2.699900e-20 1.218700e-18
      ]
    }
  }
}
