#VRML_SIM R2023b utf8
# license: Apache License 2.0
# license url: http://www.apache.org/licenses/LICENSE-2.0
# This is a proto file for Webots for the Severus1
# Extracted from: C:/Users/andyf/PycharmProjects/Pytorch_with_webots/protos/robots/Severus_1/urdf/Severus_1.urdf

PROTO Severus1 [
  field  SFVec3f     translation     0 0 0
  field  SFRotation  rotation        0 0 1 0
  field  SFString    name            "Severus1"  # Is `Robot.name`.
  field  SFString    controller      "void"      # Is `Robot.controller`.
  field  MFString    controllerArgs  []          # Is `Robot.controllerArgs`.
  field  SFString    customData      ""          # Is `Robot.customData`.
  field  SFBool      supervisor      FALSE       # Is `Robot.supervisor`.
  field  SFBool      synchronization TRUE        # Is `Robot.synchronization`.
  field  SFBool      selfCollision   FALSE       # Is `Robot.selfCollision`.
]
{
  Robot {
    translation IS translation
    rotation IS rotation
    controller IS controller
    controllerArgs IS controllerArgs
    customData IS customData
    supervisor IS supervisor
    synchronization IS synchronization
    selfCollision IS selfCollision
    children [
      Shape {
        appearance DEF base_link_material PBRAppearance {
          baseColor 0.792160 0.819610 0.933330
          roughness 1.000000
          metalness 0
        }
        geometry DEF base_link Mesh {
          url "C:/Users/andyf/PycharmProjects/Pytorch_with_webots/protos/robots/Severus_1/meshes/base_link.STL"
        }
      }
      HingeJoint {
        jointParameters HingeJointParameters {
          axis 0.000000 1.000000 -0.000004
          anchor -0.020000 0.000000 0.148120
        }
        device [
          RotationalMotor {
            name "Joint_11"
            maxTorque 10000
          }
          PositionSensor {
            name "Joint_11_sensor"
          }
        ]
        endPoint Solid {
          translation -0.020000 0.000000 0.148120
          rotation -1.000000 0.000000 0.000000 1.570800
          children [
            Shape {
              appearance DEF Link_11_material PBRAppearance {
                baseColor 0.792160 0.819610 0.933330
                roughness 1.000000
                metalness 0
              }
              geometry DEF Link_11 Mesh {
                url "C:/Users/andyf/PycharmProjects/Pytorch_with_webots/protos/robots/Severus_1/meshes/Link_11.STL"
              }
            }
            HingeJoint {
              jointParameters HingeJointParameters {
                anchor -0.017500 0.000000 0.000000
              }
              device [
                RotationalMotor {
                  name "Joint_12"
                  maxTorque 10000
                }
                PositionSensor {
                  name "Joint_12_sensor"
                }
              ]
              endPoint Solid {
                translation -0.017500 0.000000 0.000000
                rotation 1.000000 0.000000 0.000000 2.530700
                children [
                  Shape {
                    appearance DEF Link_12_material PBRAppearance {
                      baseColor 0.792160 0.819610 0.933330
                      roughness 1.000000
                      metalness 0
                    }
                    geometry DEF Link_12 Mesh {
                      url "C:/Users/andyf/PycharmProjects/Pytorch_with_webots/protos/robots/Severus_1/meshes/Link_12.STL"
                    }
                  }
                  HingeJoint {
                    jointParameters HingeJointParameters {
                      anchor -0.005000 -0.070000 0.000000
                    }
                    device [
                      RotationalMotor {
                        name "Joint_13"
                        maxTorque 10000
                      }
                      PositionSensor {
                        name "Joint_13_sensor"
                      }
                    ]
                    endPoint Solid {
                      translation -0.005000 -0.070000 0.000000
                      rotation 1.000000 0.000000 0.000000 1.134500
                      children [
                        Shape {
                          appearance DEF Link_13_material PBRAppearance {
                            baseColor 0.792160 0.819610 0.933330
                            roughness 1.000000
                            metalness 0
                          }
                          geometry DEF Link_13 Mesh {
                            url "C:/Users/andyf/PycharmProjects/Pytorch_with_webots/protos/robots/Severus_1/meshes/Link_13.STL"
                          }
                        }
                        HingeJoint {
                          jointParameters HingeJointParameters {
                            anchor 0.000000 -0.087500 0.000000
                          }
                          device [
                            RotationalMotor {
                              name "Joint_14"
                              maxTorque 10000
                            }
                            PositionSensor {
                              name "Joint_14_sensor"
                            }
                          ]
                          endPoint Solid {
                            translation 0.000000 -0.087500 0.000000
                            rotation -1.000000 0.000000 0.000000 0.523600
                            children [
                              Shape {
                                appearance DEF Link_14_material PBRAppearance {
                                  baseColor 0.792157 0.819608 0.933333
                                  roughness 1.000000
                                  metalness 0
                                }
                                geometry DEF Link_14 Mesh {
                                  url "C:/Users/andyf/PycharmProjects/Pytorch_with_webots/protos/robots/Severus_1/meshes/Link_14.STL"
                                }
                              }
                            ]
                            name "Link_14"
                            boundingObject USE Link_14
                            physics Physics {
                              density -1
                              mass 0.018034
                              centerOfMass [ -0.005000 -0.009528 0.009505 ]
                              inertiaMatrix [
                                5.053037e-06 6.057906e-06 1.457645e-06
                                -2.104098e-23 2.695719e-22 8.089062e-08
                              ]
                            }
                          }
                        }
                      ]
                      name "Link_13"
                      boundingObject USE Link_13
                      physics Physics {
                        density -1
                        mass 0.009669
                        centerOfMass [ -0.005000 -0.040482 0.000000 ]
                        inertiaMatrix [
                          7.878000e-06 3.274600e-07 7.593300e-06
                          1.653200e-21 -3.443700e-23 8.999700e-22
                        ]
                      }
                    }
                  }
                ]
                name "Link_12"
                boundingObject USE Link_12
                physics Physics {
                  density -1
                  mass 0.025410
                  centerOfMass [ -0.009884 -0.027374 0.000000 ]
                  inertiaMatrix [
                    1.894700e-05 2.101800e-06 1.735700e-05
                    -8.062400e-08 -1.522000e-22 -9.211500e-21
                  ]
                }
              }
            }
          ]
          name "Link_11"
          boundingObject USE Link_11
          physics Physics {
            density -1
            mass 0.003353
            centerOfMass [ -0.005742 0.000000 -0.000000 ]
            inertiaMatrix [
              1.244100e-07 1.943500e-07 2.028700e-07
              -9.572400e-24 -2.451100e-24 2.629600e-25
            ]
          }
        }
      }
      HingeJoint {
        jointParameters HingeJointParameters {
          axis -0.000007 1.000000 -0.000004
          anchor 0.020000 0.000000 0.148120
        }
        device [
          RotationalMotor {
            name "Joint_21"
            maxTorque 10000
          }
          PositionSensor {
            name "Joint_21_sensor"
          }
        ]
        endPoint Solid {
          translation 0.020000 0.000000 0.148120
          rotation -0.000003 0.707108 0.707105 3.141598
          children [
            Shape {
              appearance DEF Link_21_material PBRAppearance {
                baseColor 0.792157 0.819608 0.933333
                roughness 1.000000
                metalness 0
              }
              geometry DEF Link_21 Mesh {
                url "C:/Users/andyf/PycharmProjects/Pytorch_with_webots/protos/robots/Severus_1/meshes/Link_21.STL"
              }
            }
            HingeJoint {
              jointParameters HingeJointParameters {
                anchor -0.017500 0.000000 0.000000
              }
              device [
                RotationalMotor {
                  name "Joint_22"
                  maxTorque 10000
                }
                PositionSensor {
                  name "Joint_22_sensor"
                }
              ]
              endPoint Solid {
                translation -0.017500 0.000000 0.000000
                rotation 1.000000 0.000000 0.000000 0.610870
                children [
                  Shape {
                    appearance DEF Link_22_material PBRAppearance {
                      baseColor 0.792157 0.819608 0.933333
                      roughness 1.000000
                      metalness 0
                    }
                    geometry DEF Link_22 Mesh {
                      url "C:/Users/andyf/PycharmProjects/Pytorch_with_webots/protos/robots/Severus_1/meshes/Link_22.STL"
                    }
                  }
                  HingeJoint {
                    jointParameters HingeJointParameters {
                      anchor -0.005000 -0.070000 0.000000
                    }
                    device [
                      RotationalMotor {
                        name "Joint_23"
                        maxTorque 10000
                      }
                      PositionSensor {
                        name "Joint_23_sensor"
                      }
                    ]
                    endPoint Solid {
                      translation -0.005000 -0.070000 0.000000
                      rotation -1.000000 0.000000 0.000000 1.134500
                      children [
                        Shape {
                          appearance DEF Link_23_material PBRAppearance {
                            baseColor 0.792157 0.819608 0.933333
                            roughness 1.000000
                            metalness 0
                          }
                          geometry DEF Link_23 Mesh {
                            url "C:/Users/andyf/PycharmProjects/Pytorch_with_webots/protos/robots/Severus_1/meshes/Link_23.STL"
                          }
                        }
                        HingeJoint {
                          jointParameters HingeJointParameters {
                            axis -1.000000 -0.000007 0.000000
                            anchor 0.000000 -0.087500 0.000000
                          }
                          device [
                            RotationalMotor {
                              name "Joint_24"
                              maxTorque 10000
                            }
                            PositionSensor {
                              name "Joint_24_sensor"
                            }
                          ]
                          endPoint Solid {
                            translation 0.000000 -0.087500 0.000000
                            rotation -0.000004 0.965927 0.258816 3.141595
                            children [
                              Shape {
                                appearance DEF Link_24_material PBRAppearance {
                                  baseColor 0.792157 0.819608 0.933333
                                  roughness 1.000000
                                  metalness 0
                                }
                                geometry DEF Link_24 Mesh {
                                  url "C:/Users/andyf/PycharmProjects/Pytorch_with_webots/protos/robots/Severus_1/meshes/Link_24.STL"
                                }
                              }
                            ]
                            name "Link_24"
                            boundingObject USE Link_24
                            physics Physics {
                              density -1
                              mass 0.018034
                              centerOfMass [ 0.005000 -0.009528 0.009505 ]
                              inertiaMatrix [
                                5.053037e-06 6.057906e-06 1.457645e-06
                                -7.478989e-23 -7.822896e-23 8.089062e-08
                              ]
                            }
                          }
                        }
                      ]
                      name "Link_23"
                      boundingObject USE Link_23
                      physics Physics {
                        density -1
                        mass 0.009669
                        centerOfMass [ -0.005000 -0.040482 0.000000 ]
                        inertiaMatrix [
                          7.878045e-06 3.274608e-07 7.593326e-06
                          -1.957283e-23 -1.138445e-23 2.355810e-21
                        ]
                      }
                    }
                  }
                ]
                name "Link_22"
                boundingObject USE Link_22
                physics Physics {
                  density -1
                  mass 0.025410
                  centerOfMass [ -0.009884 -0.027374 -0.000000 ]
                  inertiaMatrix [
                    1.894688e-05 2.101756e-06 1.735743e-05
                    -8.062379e-08 -1.588187e-22 -1.016440e-20
                  ]
                }
              }
            }
          ]
          name "Link_21"
          boundingObject USE Link_21
          physics Physics {
            density -1
            mass 0.003352
            centerOfMass [ -0.005742 0.000000 -0.000000 ]
            inertiaMatrix [
              1.244134e-07 1.943516e-07 2.028652e-07
              -3.068876e-25 1.802091e-24 1.042580e-24
            ]
          }
        }
      }
    ]
    name IS name
    boundingObject USE base_link
    physics Physics {
      density -1
      mass 0.024892
      centerOfMass [ -0.000000 0.162140 0.000000 ]
      inertiaMatrix [
        1.035300e-05 1.562700e-05 7.541300e-06
        -1.092300e-21 -9.305800e-22 3.341700e-22
      ]
    }
  }
}
