#VRML_SIM R2023b utf8

EXTERNPROTO "https://raw.githubusercontent.com/cyberbotics/webots/R2023b/projects/objects/backgrounds/protos/TexturedBackground.proto"
EXTERNPROTO "https://raw.githubusercontent.com/cyberbotics/webots/R2023b/projects/objects/backgrounds/protos/TexturedBackgroundLight.proto"
EXTERNPROTO "https://raw.githubusercontent.com/cyberbotics/webots/R2023b/projects/objects/floors/protos/RectangleArena.proto"

WorldInfo {
  basicTimeStep 64
}
Viewpoint {
  orientation -0.40968955533566637 0.46865715496419075 0.7826333364671699 1.3813583796445
  position -5.273134217892623 -16.448052484539705 15.06424802492536
}
TexturedBackground {
}
TexturedBackgroundLight {
}
RectangleArena {
  translation 0 -3.99 -0.2
  floorSize 3 10
  floorTileSize 1 1
}
DEF Node_base Robot {
  translation -3.39497282643951e-06 3.4672950258600455e-05 -0.02456989000752005
  rotation 0.02728991505068179 -0.9995951981457302 0.008043654674661317 0.023681118402225535
  children [
    Shape {
      appearance DEF mat PBRAppearance {
        roughness 1
        metalness 0
      }
      geometry DEF base_link Mesh {
        url [
          "C:/Users/andyf/PycharmProjects/Pytorch_with_webots/protos/robots/FirstTry0314/meshes/base_link.STL"
        ]
      }
    }
    HingeJoint {
      jointParameters HingeJointParameters {
        position -1.298558651301727e-05
        axis -1 -4e-06 0
        anchor 0.091803 -0.25 0.012279
      }
      device [
        RotationalMotor {
          name "Joint-11"
          maxTorque 10000
        }
        PositionSensor {
          name "Joint-11_sensor"
        }
      ]
      endPoint Solid {
        translation 0.091803 -0.25 0.012279
        rotation 0.5694005523370851 -0.5693985523289826 0.5929319519168126 2.0711843939536574
        children [
          Shape {
            appearance USE mat
            geometry DEF Link-11 Mesh {
              url [
                "C:/Users/andyf/PycharmProjects/Pytorch_with_webots/protos/robots/FirstTry0314/meshes/Link-11.STL"
              ]
            }
          }
          HingeJoint {
            jointParameters HingeJointParameters {
              position -1.0792082005551797e-07
              axis -1 -4e-06 0
              anchor 0.037602 -0.05 0
            }
            device [
              RotationalMotor {
                name "Joint-12"
                maxTorque 10000
              }
              PositionSensor {
                name "Joint-12_sensor"
              }
            ]
            endPoint Solid {
              translation 0.037602 -0.05 0
              rotation 0.5615993470205516 -0.561597347019305 0.6076303096842426 2.0495740606080117
              children [
                Shape {
                  appearance USE mat
                  geometry DEF Link-12 Mesh {
                    url [
                      "C:/Users/andyf/PycharmProjects/Pytorch_with_webots/protos/robots/FirstTry0314/meshes/Link-12.STL"
                    ]
                  }
                }
                HingeJoint {
                  jointParameters HingeJointParameters {
                    position -2.3783651932153452e-06
                    axis 1 7e-06 -1e-06
                    anchor 0 -0.037398 0.025
                  }
                  device [
                    RotationalMotor {
                      name "Joint-13"
                      maxTorque 10000
                    }
                    PositionSensor {
                      name "Joint-13_sensor"
                    }
                  ]
                  endPoint Solid {
                    translation 0 -0.037398 0.025
                    rotation 0.7044901067428718 0.08594986326011851 0.7044901067488342 2.9701243244654334
                    children [
                      Shape {
                        appearance USE mat
                        geometry DEF Link-13 Mesh {
                          url [
                            "C:/Users/andyf/PycharmProjects/Pytorch_with_webots/protos/robots/FirstTry0314/meshes/Link-13.STL"
                          ]
                        }
                      }
                      HingeJoint {
                        jointParameters HingeJointParameters {
                          position 1.7200954231101218e-06
                          axis 4e-06 -6e-06 -1
                          anchor 0 0.2 0
                        }
                        device [
                          RotationalMotor {
                            name "Joint-14"
                            maxTorque 10000
                          }
                          PositionSensor {
                            name "Joint-14_sensor"
                          }
                        ]
                        endPoint Solid {
                          translation 0 0.2 0
                          rotation -0.947520122304108 -0.31969613358282667 -1.000002669016969e-06 3.1415999999985003
                          children [
                            Shape {
                              appearance USE mat
                              geometry DEF Link-14 Mesh {
                                url [
                                  "C:/Users/andyf/PycharmProjects/Pytorch_with_webots/protos/robots/FirstTry0314/meshes/Link-14.STL"
                                ]
                              }
                            }
                          ]
                          name "Link-14"
                          boundingObject USE Link-14
                          physics Physics {
                            density -1
                            mass 1.3182
                            centerOfMass [
                              0.047942 0.21275 0.00054
                            ]
                            inertiaMatrix [
                              0.028713 0.00066838 0.028833
                              -0.00057712 3.2444e-05 0.00015134
                            ]
                          }
                          linearVelocity 2.155956188257267e-05 6.419411291166961e-05 -3.358685253998297e-05
                          angularVelocity 0.00021186403679824585 2.566396382685821e-05 6.600864019046823e-05
                        }
                      }
                    ]
                    name "Link-13"
                    boundingObject USE Link-13
                    physics Physics {
                      density -1
                      mass 0.49632
                      centerOfMass [
                        0 0.1 0.002867
                      ]
                      inertiaMatrix [
                        0.0019227 0.00020011 0.0019242
                        -1.2535e-18 2.7105e-20 -5.7725e-19
                      ]
                    }
                    linearVelocity 2.2725933401176077e-05 3.8128028139183e-05 -2.7166992557576674e-05
                    angularVelocity 0.00021187094711275423 2.5661630692157195e-05 6.601360244209071e-05
                  }
                }
              ]
              name "Link-12"
              boundingObject USE Link-12
              physics Physics {
                density -1
                mass 0.12291
                centerOfMass [
                  -0.005788 -0.036825 0.004011
                ]
                inertiaMatrix [
                  7.6838e-05 7.1867e-05 4.7075e-05
                  -4.075e-07 1.327e-05 2.8244e-07
                ]
              }
              linearVelocity 1.9652332570251205e-05 5.638820501514909e-05 -2.4362017723549782e-05
              angularVelocity 0.00021187185398049312 2.5663346217538296e-05 6.601983586855905e-05
            }
          }
        ]
        name "Link-11"
        boundingObject USE Link-11
        physics Physics {
          density -1
          mass 0.13426
          centerOfMass [
            0.000524 -0.048741 0
          ]
          inertiaMatrix [
            5.9611e-05 5.5476e-05 6.1772e-05
            8.862e-08 -1.2705e-21 -8.8508e-22
          ]
        }
        linearVelocity 1.8328819525005778e-05 7.17883342861717e-05 -2.6060137133020283e-05
        angularVelocity 0.00021187156298038793 2.5668058242629156e-05 6.602524975534239e-05
      }
    }
    HingeJoint {
      jointParameters HingeJointParameters {
        position -4.5412057955671896e-05
        axis 1 1.1e-05 -1e-06
        anchor -0.1082 -0.25 0.012279
      }
      device [
        RotationalMotor {
          name "Joint-21"
          maxTorque 10000
        }
        PositionSensor {
          name "Joint-21_sensor"
        }
      ]
      endPoint Solid {
        translation -0.1082 -0.25 0.012279
        rotation 0.5983155900222296 0.5983215901212223 0.532944396284606 4.120911829159491
        children [
          Shape {
            appearance USE mat
            geometry DEF Link-21 Mesh {
              url [
                "C:/Users/andyf/PycharmProjects/Pytorch_with_webots/protos/robots/FirstTry0314/meshes/Link-21.STL"
              ]
            }
          }
          HingeJoint {
            jointParameters HingeJointParameters {
              position -5.7437288866689594e-05
              axis -1 1.1e-05 0
              anchor 0.038328 -0.05 0
            }
            device [
              RotationalMotor {
                name "Joint-22"
                maxTorque 10000
              }
              PositionSensor {
                name "Joint-22_sensor"
              }
            ]
            endPoint Solid {
              translation 0.038328 -0.05 0
              rotation -0.5844226111061764 0.5844286112093988 -0.5629328645830621 4.167039432286149
              children [
                Shape {
                  appearance USE mat
                  geometry DEF Link-22 Mesh {
                    url [
                      "C:/Users/andyf/PycharmProjects/Pytorch_with_webots/protos/robots/FirstTry0314/meshes/Link-22.STL"
                    ]
                  }
                }
                HingeJoint {
                  jointParameters HingeJointParameters {
                    position 3.7078944740719554e-05
                    axis 1 7e-06 -1e-06
                    anchor 0 -0.036672 0.025
                  }
                  device [
                    RotationalMotor {
                      name "Joint-23"
                      maxTorque 10000
                    }
                    PositionSensor {
                      name "Joint-23_sensor"
                    }
                  ]
                  endPoint Solid {
                    translation 0 -0.036672 0.025
                    rotation 0.7038903558847837 0.09527189468699919 0.7038903557906885 2.9516320994937115
                    children [
                      Shape {
                        appearance USE mat
                        geometry DEF Link-23 Mesh {
                          url [
                            "C:/Users/andyf/PycharmProjects/Pytorch_with_webots/protos/robots/FirstTry0314/meshes/Link-23.STL"
                          ]
                        }
                      }
                      HingeJoint {
                        jointParameters HingeJointParameters {
                          position -2.897776570957902e-05
                          axis -4e-06 6e-06 -1
                          anchor 0 0.2 0
                        }
                        device [
                          RotationalMotor {
                            name "Joint-24"
                            maxTorque 10000
                          }
                          PositionSensor {
                            name "Joint-24_sensor"
                          }
                        ]
                        endPoint Solid {
                          translation 0 0.2 0
                          rotation 0.9662948482387852 0.25743788817146435 -9.99953861279792e-07 3.141600000038269
                          children [
                            Shape {
                              appearance USE mat
                              geometry DEF Link-24 Mesh {
                                url [
                                  "C:/Users/andyf/PycharmProjects/Pytorch_with_webots/protos/robots/FirstTry0314/meshes/Link-24.STL"
                                ]
                              }
                            }
                          ]
                          name "Link-24"
                          boundingObject USE Link-24
                          physics Physics {
                            density -1
                            mass 1.3182
                            centerOfMass [
                              0.047942 0.21275 0.00054
                            ]
                            inertiaMatrix [
                              0.028713 0.00066838 0.028833
                              -0.00057712 3.2444e-05 0.00015134
                            ]
                          }
                          linearVelocity 1.1702549847527863e-05 6.177553639806821e-05 -8.099325103876206e-06
                          angularVelocity -0.00018712547158301885 5.471782475156053e-05 0.00028465382438776004
                        }
                      }
                    ]
                    name "Link-23"
                    boundingObject USE Link-23
                    physics Physics {
                      density -1
                      mass 0.49632
                      centerOfMass [
                        0 0.1 0.002867
                      ]
                      inertiaMatrix [
                        0.0019227 0.00020011 0.0019242
                        1.527e-18 -2.7105e-20 1.6348e-18
                      ]
                    }
                    linearVelocity 1.4094339420848216e-05 0.00010392438909841113 -1.8656310174667616e-05
                    angularVelocity -0.00019216413032282175 5.461076614745414e-05 0.0002863479278819851
                  }
                }
              ]
              name "Link-22"
              boundingObject USE Link-22
              physics Physics {
                density -1
                mass 0.12291
                centerOfMass [
                  -0.005788 -0.036099 0.004011
                ]
                inertiaMatrix [
                  7.6838e-05 7.1867e-05 4.7075e-05
                  -4.075e-07 1.327e-05 2.8244e-07
                ]
              }
              linearVelocity 1.6520775873425695e-05 8.909079624626692e-05 -1.815942208748225e-05
              angularVelocity -0.0001950661936979325 5.418819162961395e-05 0.0002887220646855217
            }
          }
        ]
        name "Link-21"
        boundingObject USE Link-21
        physics Physics {
          density -1
          mass 0.13426
          centerOfMass [
            0.000524 -0.048741 0
          ]
          inertiaMatrix [
            5.9611e-05 5.5476e-05 6.1772e-05
            8.862e-08 1.6941e-21 1.4029e-21
          ]
        }
        linearVelocity 1.572625901440614e-05 6.514682600231287e-05 -1.8214683903337867e-05
        angularVelocity -0.00019191959244509163 2.6119605122537126e-05 5.318775838920302e-05
      }
    }
    HingeJoint {
      jointParameters HingeJointParameters {
        position -4.163497397195135e-06
        axis -1 -4e-06 0
        anchor 0.091803 0.05 0.012279
      }
      device [
        RotationalMotor {
          name "Joint-31"
          maxTorque 10000
        }
        PositionSensor {
          name "Joint-31_sensor"
        }
      ]
      endPoint Solid {
        translation 0.091803 0.05 0.012279
        rotation 0.5693987848476909 -0.5693967848452097 0.592935346578285 2.071179370679133
        children [
          Shape {
            appearance USE mat
            geometry DEF Link-31 Mesh {
              url [
                "C:/Users/andyf/PycharmProjects/Pytorch_with_webots/protos/robots/FirstTry0314/meshes/Link-31.STL"
              ]
            }
          }
          HingeJoint {
            jointParameters HingeJointParameters {
              position 9.457041306119953e-06
              axis -1 -4e-06 0
              anchor 0.037602 -0.05 0
            }
            device [
              RotationalMotor {
                name "Joint-32"
                maxTorque 10000
              }
              PositionSensor {
                name "Joint-32_sensor"
              }
            ]
            endPoint Solid {
              translation 0.037602 -0.05 0
              rotation 0.5615973575521026 -0.5615953575587674 0.607633987165741 2.0495686889625238
              children [
                Shape {
                  appearance USE mat
                  geometry DEF Link-32 Mesh {
                    url [
                      "C:/Users/andyf/PycharmProjects/Pytorch_with_webots/protos/robots/FirstTry0314/meshes/Link-32.STL"
                    ]
                  }
                }
                HingeJoint {
                  jointParameters HingeJointParameters {
                    position 5.904688343206907e-05
                    axis 1 7e-06 -1e-06
                    anchor 0 -0.037398 0.025
                  }
                  device [
                    RotationalMotor {
                      name "Joint-33"
                      maxTorque 10000
                    }
                    PositionSensor {
                      name "Joint-33_sensor"
                    }
                  ]
                  endPoint Solid {
                    translation 0 -0.037398 0.025
                    rotation 0.7038956883798865 0.0951930667992696 0.7038956882333884 2.951788562802576
                    children [
                      Shape {
                        appearance USE mat
                        geometry DEF Link-33 Mesh {
                          url [
                            "C:/Users/andyf/PycharmProjects/Pytorch_with_webots/protos/robots/FirstTry0314/meshes/Link-33.STL"
                          ]
                        }
                      }
                      HingeJoint {
                        jointParameters HingeJointParameters {
                          position -4.452351056038157e-05
                          axis 3e-06 -7e-06 -1
                          anchor 0 0.2 0
                        }
                        device [
                          RotationalMotor {
                            name "Joint-34"
                            maxTorque 10000
                          }
                          PositionSensor {
                            name "Joint-34_sensor"
                          }
                        ]
                        endPoint Solid {
                          translation 0 0.2 0
                          rotation -0.9815859705537522 -0.19102089522104232 -9.999162793235628e-07 3.1416000000270583
                          children [
                            Shape {
                              appearance USE mat
                              geometry DEF Link-34 Mesh {
                                url [
                                  "C:/Users/andyf/PycharmProjects/Pytorch_with_webots/protos/robots/FirstTry0314/meshes/Link-34.STL"
                                ]
                              }
                            }
                          ]
                          name "Link-34"
                          boundingObject USE Link-34
                          physics Physics {
                            density -1
                            mass 1.3182
                            centerOfMass [
                              0.047942 0.21275 0.00054
                            ]
                            inertiaMatrix [
                              0.028713 0.00066838 0.028833
                              -0.00057712 3.2444e-05 0.00015134
                            ]
                          }
                          linearVelocity 5.696262868867659e-06 5.765970043645946e-05 -1.407913634467344e-06
                          angularVelocity -0.00019805543883147435 1.4363720544057469e-05 -0.00017503710252440483
                        }
                      }
                    ]
                    name "Link-33"
                    boundingObject USE Link-33
                    physics Physics {
                      density -1
                      mass 0.49632
                      centerOfMass [
                        0 0.1 0.002867
                      ]
                      inertiaMatrix [
                        0.0019227 0.00020011 0.0019242
                        -1.9327e-18 5.421e-20 -2.8376e-19
                      ]
                    }
                    linearVelocity 7.024598898537939e-06 9.689517905897503e-05 -1.6880312701189297e-06
                    angularVelocity -0.0001979208880831492 1.5157900670110593e-05 -0.00017623248939436156
                  }
                }
              ]
              name "Link-32"
              boundingObject USE Link-32
              physics Physics {
                density -1
                mass 0.12291
                centerOfMass [
                  -0.005788 -0.036825 0.004011
                ]
                inertiaMatrix [
                  7.6838e-05 7.1867e-05 4.7075e-05
                  -4.075e-07 1.327e-05 2.8244e-07
                ]
              }
              linearVelocity 5.391365072532035e-06 8.558906229963341e-05 -2.716804433449688e-06
              angularVelocity -0.00019785579429457172 1.5566305515736424e-05 -0.00017740358709378306
            }
          }
        ]
        name "Link-31"
        boundingObject USE Link-31
        physics Physics {
          density -1
          mass 0.13426
          centerOfMass [
            0.000524 -0.048741 0
          ]
          inertiaMatrix [
            5.9611e-05 5.5476e-05 6.1772e-05
            8.862e-08 -5.294e-21 2.3868e-21
          ]
        }
        linearVelocity 1.0953932228328721e-06 7.174483023669472e-05 -1.0133503392713352e-06
        angularVelocity -0.0002033984470232289 2.5313804571624524e-05 5.734768942953635e-05
      }
    }
    HingeJoint {
      jointParameters HingeJointParameters {
        position 5.12684435546536e-05
        axis 1 1.1e-05 -1e-06
        anchor -0.1082 0.05 0.012279
      }
      device [
        RotationalMotor {
          name "Joint-41"
          maxTorque 10000
        }
        PositionSensor {
          name "Joint-41_sensor"
        }
      ]
      endPoint Solid {
        translation -0.1082 0.05 0.012279
        rotation 0.6000517552769729 0.6000577551693688 0.5290260687812295 4.114798764253293
        children [
          Shape {
            appearance USE mat
            geometry DEF Link-41 Mesh {
              url [
                "C:/Users/andyf/PycharmProjects/Pytorch_with_webots/protos/robots/FirstTry0314/meshes/Link-41.STL"
              ]
            }
          }
          HingeJoint {
            jointParameters HingeJointParameters {
              position -7.196352168464809e-06
              axis -1 -4e-06 0
              anchor 0.038483 -0.05 0
            }
            device [
              RotationalMotor {
                name "Joint-42"
                maxTorque 10000
              }
              PositionSensor {
                name "Joint-42_sensor"
              }
            ]
            endPoint Solid {
              translation 0.038483 -0.05 0
              rotation 0.5844156789170222 -0.5844136789102264 0.5629555632006586 2.1161252056394035
              children [
                Shape {
                  appearance USE mat
                  geometry DEF Link-42 Mesh {
                    url [
                      "C:/Users/andyf/PycharmProjects/Pytorch_with_webots/protos/robots/FirstTry0314/meshes/Link-42.STL"
                    ]
                  }
                }
                HingeJoint {
                  jointParameters HingeJointParameters {
                    position -5.512759595034716e-06
                    axis 1 7e-06 -1e-06
                    anchor 0 -0.036517 0.025
                  }
                  device [
                    RotationalMotor {
                      name "Joint-43"
                      maxTorque 10000
                    }
                    PositionSensor {
                      name "Joint-43_sensor"
                    }
                  ]
                  endPoint Solid {
                    translation 0 -0.036517 0.025
                    rotation 0.7049404087867007 0.07821790140788844 0.7049404087999107 2.985485113833565
                    children [
                      Shape {
                        appearance USE mat
                        geometry DEF Link-43 Mesh {
                          url [
                            "C:/Users/andyf/PycharmProjects/Pytorch_with_webots/protos/robots/FirstTry0314/meshes/Link-43.STL"
                          ]
                        }
                      }
                      HingeJoint {
                        jointParameters HingeJointParameters {
                          position 5.869301767912259e-06
                          axis 3e-06 -7e-06 -1
                          anchor 0 0.2 0
                        }
                        device [
                          RotationalMotor {
                            name "Joint-44"
                            maxTorque 10000
                          }
                          PositionSensor {
                            name "Joint-44_sensor"
                          }
                        ]
                        endPoint Solid {
                          translation 0 0.2 0
                          rotation -0.9722548411532865 -0.23392418398489195 -1.0000114115663088e-06 3.141599999998361
                          children [
                            Shape {
                              appearance USE mat
                              geometry DEF Link-44 Mesh {
                                url [
                                  "C:/Users/andyf/PycharmProjects/Pytorch_with_webots/protos/robots/FirstTry0314/meshes/Link-44.STL"
                                ]
                              }
                            }
                          ]
                          name "Link-44"
                          boundingObject USE Link-44
                          physics Physics {
                            density -1
                            mass 1.3182
                            centerOfMass [
                              0.047942 0.21275 0.00054
                            ]
                            inertiaMatrix [
                              0.028713 0.00066838 0.028833
                              -0.00057712 3.2444e-05 0.00015134
                            ]
                          }
                          linearVelocity 3.68018764687115e-06 1.0370866293989493e-05 8.423934094969885e-06
                          angularVelocity -2.3788337321192486e-05 1.70667316380235e-05 4.098462833581343e-06
                        }
                      }
                    ]
                    name "Link-43"
                    boundingObject USE Link-43
                    physics Physics {
                      density -1
                      mass 0.49632
                      centerOfMass [
                        0 0.1 0.002867
                      ]
                      inertiaMatrix [
                        0.0019227 0.00020011 0.0019242
                        1.3239e-18 2.7105e-20 -4.3707e-19
                      ]
                    }
                    linearVelocity 4.503452054040232e-06 2.4308992735826742e-05 6.18466206165597e-06
                    angularVelocity -1.8942946681718635e-05 1.6422001948147745e-05 2.630205184027416e-06
                  }
                }
              ]
              name "Link-42"
              boundingObject USE Link-42
              physics Physics {
                density -1
                mass 0.12291
                centerOfMass [
                  -0.005788 -0.035945 0.004011
                ]
                inertiaMatrix [
                  7.6838e-05 7.1867e-05 4.7075e-05
                  -4.075e-07 1.327e-05 2.8244e-07
                ]
              }
              linearVelocity 2.1645698584228585e-06 3.3270411931692375e-05 6.0652219535475715e-06
              angularVelocity -1.6197504936785686e-05 1.692801858926368e-05 4.991690688474921e-07
            }
          }
        ]
        name "Link-41"
        boundingObject USE Link-41
        physics Physics {
          density -1
          mass 0.13426
          centerOfMass [
            0.000524 -0.048741 0
          ]
          inertiaMatrix [
            5.9611e-05 5.5476e-05 6.1772e-05
            8.862e-08 0 1.4261e-21
          ]
        }
        linearVelocity 8.306619174550988e-08 4.294020895904873e-05 6.269858210583368e-06
        angularVelocity -1.5377469632875305e-05 2.540317934997071e-05 6.36152801711397e-05
      }
    }
  ]
  name "FirstTry0314"
  boundingObject USE base_link
  physics Physics {
    density -1
    mass 1.3313
    centerOfMass [
      -0.008197 -0.00733 0.1
    ]
    inertiaMatrix [
      0.020645 0.023213 0.0034844
      -3.7461e-19 -2.6999e-20 1.2187e-18
    ]
  }
  controller "<extern>"
  supervisor TRUE
  linearVelocity 5.214308368219626e-06 5.5404612101550706e-05 -1.9774776794027372e-06
  angularVelocity 8.343966593216405e-05 2.5650761336260596e-05 6.299337738540313e-05
}
