#VRML_SIM R2023b utf8

EXTERNPROTO "https://raw.githubusercontent.com/cyberbotics/webots/R2023b/projects/objects/backgrounds/protos/TexturedBackground.proto"
EXTERNPROTO "https://raw.githubusercontent.com/cyberbotics/webots/R2023b/projects/objects/backgrounds/protos/TexturedBackgroundLight.proto"
EXTERNPROTO "https://raw.githubusercontent.com/cyberbotics/webots/R2023b/projects/objects/floors/protos/RectangleArena.proto"

WorldInfo {
  basicTimeStep 64
}
Viewpoint {
  orientation -0.40968955533566637 0.46865715496419075 0.7826333364671699 1.3813583796445
  position -5.273134217892623 -16.448052484539705 15.06424802492536
}
TexturedBackground {
}
TexturedBackgroundLight {
}
RectangleArena {
  translation 0 -3.99 -0.2
  floorSize 3 10
  floorTileSize 1 1
}
DEF Node_base Robot {
  rotation 0.026541079084510703 -0.9996234620163581 0.006964575181619771 0.02368647047007125
  children [
    Shape {
      appearance DEF mat PBRAppearance {
        roughness 1
        metalness 0
      }
      geometry DEF base_link Mesh {
        url [
          "C:/Users/andyf/PycharmProjects/Pytorch_with_webots/protos/robots/FirstTry0314/meshes/base_link.STL"
        ]
      }
    }
    HingeJoint {
      jointParameters HingeJointParameters {
        position -1.3880393311354903e-07
        axis -1 -4e-06 0
        anchor 0.091803 -0.25 0.012279
      }
      device [
        RotationalMotor {
          name "Joint-11"
          maxTorque 10000
        }
        PositionSensor {
          name "Joint-11_sensor"
        }
      ]
      endPoint Solid {
        translation 0.091803 -0.25 0.012279
        rotation 0.5693979785026185 -0.5693959785027033 0.5929368952444103 2.071177079034353
        children [
          Shape {
            appearance USE mat
            geometry DEF Link-11 Mesh {
              url [
                "C:/Users/andyf/PycharmProjects/Pytorch_with_webots/protos/robots/FirstTry0314/meshes/Link-11.STL"
              ]
            }
          }
          HingeJoint {
            jointParameters HingeJointParameters {
              position -9.595877416055948e-06
              axis -1 -4e-06 0
              anchor 0.037602 -0.05 0
            }
            device [
              RotationalMotor {
                name "Joint-12"
                maxTorque 10000
              }
              PositionSensor {
                name "Joint-12_sensor"
              }
            ]
            endPoint Solid {
              translation 0.037602 -0.05 0
              rotation 0.5616013204538884 -0.561599320444796 0.6076266618083774 2.0495793890262886
              children [
                Shape {
                  appearance USE mat
                  geometry DEF Link-12 Mesh {
                    url [
                      "C:/Users/andyf/PycharmProjects/Pytorch_with_webots/protos/robots/FirstTry0314/meshes/Link-12.STL"
                    ]
                  }
                }
                HingeJoint {
                  jointParameters HingeJointParameters {
                    position -2.6915479542374526e-06
                    axis 1 7e-06 -1e-06
                    anchor 0 -0.037398 0.025
                  }
                  device [
                    RotationalMotor {
                      name "Joint-13"
                      maxTorque 10000
                    }
                    PositionSensor {
                      name "Joint-13_sensor"
                    }
                  ]
                  endPoint Solid {
                    translation 0 -0.037398 0.025
                    rotation 0.7044900999632594 0.08594997439211986 0.7044900999700071 2.97012410383131
                    children [
                      Shape {
                        appearance USE mat
                        geometry DEF Link-13 Mesh {
                          url [
                            "C:/Users/andyf/PycharmProjects/Pytorch_with_webots/protos/robots/FirstTry0314/meshes/Link-13.STL"
                          ]
                        }
                      }
                      HingeJoint {
                        jointParameters HingeJointParameters {
                          position 2.0622142283955736e-06
                          axis 4e-06 -6e-06 -1
                          anchor 0 0.2 0
                        }
                        device [
                          RotationalMotor {
                            name "Joint-14"
                            maxTorque 10000
                          }
                          PositionSensor {
                            name "Joint-14_sensor"
                          }
                        ]
                        endPoint Solid {
                          translation 0 0.2 0
                          rotation -0.9475201769911237 -0.31969597150059587 -1.0000032319222862e-06 3.141599999998202
                          children [
                            Shape {
                              appearance USE mat
                              geometry DEF Link-14 Mesh {
                                url [
                                  "C:/Users/andyf/PycharmProjects/Pytorch_with_webots/protos/robots/FirstTry0314/meshes/Link-14.STL"
                                ]
                              }
                            }
                          ]
                          name "Link-14"
                          boundingObject USE Link-14
                          physics Physics {
                            density -1
                            mass 1.3182
                            centerOfMass [
                              0.047942 0.21275 0.00054
                            ]
                            inertiaMatrix [
                              0.028713 0.00066838 0.028833
                              -0.00057712 3.2444e-05 0.00015134
                            ]
                          }
                        }
                      }
                    ]
                    name "Link-13"
                    boundingObject USE Link-13
                    physics Physics {
                      density -1
                      mass 0.49632
                      centerOfMass [
                        0 0.1 0.002867
                      ]
                      inertiaMatrix [
                        0.0019227 0.00020011 0.0019242
                        -1.2535e-18 2.7105e-20 -5.7725e-19
                      ]
                    }
                  }
                }
              ]
              name "Link-12"
              boundingObject USE Link-12
              physics Physics {
                density -1
                mass 0.12291
                centerOfMass [
                  -0.005788 -0.036825 0.004011
                ]
                inertiaMatrix [
                  7.6838e-05 7.1867e-05 4.7075e-05
                  -4.075e-07 1.327e-05 2.8244e-07
                ]
              }
            }
          }
        ]
        name "Link-11"
        boundingObject USE Link-11
        physics Physics {
          density -1
          mass 0.13426
          centerOfMass [
            0.000524 -0.048741 0
          ]
          inertiaMatrix [
            5.9611e-05 5.5476e-05 6.1772e-05
            8.862e-08 -1.2705e-21 -8.8508e-22
          ]
        }
      }
    }
    HingeJoint {
      jointParameters HingeJointParameters {
        position -1.7447736676887048e-05
        axis 1 1.1e-05 -1e-06
        anchor -0.1082 -0.25 0.012279
      }
      device [
        RotationalMotor {
          name "Joint-21"
          maxTorque 10000
        }
        PositionSensor {
          name "Joint-21_sensor"
        }
      ]
      endPoint Solid {
        translation -0.1082 -0.25 0.012279
        rotation 0.5983108058730069 0.5983168059099326 0.5329551382070811 4.120928560751127
        children [
          Shape {
            appearance USE mat
            geometry DEF Link-21 Mesh {
              url [
                "C:/Users/andyf/PycharmProjects/Pytorch_with_webots/protos/robots/FirstTry0314/meshes/Link-21.STL"
              ]
            }
          }
          HingeJoint {
            jointParameters HingeJointParameters {
              position -3.276180062960646e-05
              axis -1 1.1e-05 0
              anchor 0.038328 -0.05 0
            }
            device [
              RotationalMotor {
                name "Joint-22"
                maxTorque 10000
              }
              PositionSensor {
                name "Joint-22_sensor"
              }
            ]
            endPoint Solid {
              translation 0.038328 -0.05 0
              rotation -0.584418037947758 0.5844240380064863 -0.5629423600347426 4.167053853301622
              children [
                Shape {
                  appearance USE mat
                  geometry DEF Link-22 Mesh {
                    url [
                      "C:/Users/andyf/PycharmProjects/Pytorch_with_webots/protos/robots/FirstTry0314/meshes/Link-22.STL"
                    ]
                  }
                }
                HingeJoint {
                  jointParameters HingeJointParameters {
                    position 3.0642044757314183e-05
                    axis 1 7e-06 -1e-06
                    anchor 0 -0.036672 0.025
                  }
                  device [
                    RotationalMotor {
                      name "Joint-23"
                      maxTorque 10000
                    }
                    PositionSensor {
                      name "Joint-23_sensor"
                    }
                  ]
                  endPoint Solid {
                    translation 0 -0.036672 0.025
                    rotation 0.7038902011692872 0.09527418068495551 0.7038902010915272 2.951627568622628
                    children [
                      Shape {
                        appearance USE mat
                        geometry DEF Link-23 Mesh {
                          url [
                            "C:/Users/andyf/PycharmProjects/Pytorch_with_webots/protos/robots/FirstTry0314/meshes/Link-23.STL"
                          ]
                        }
                      }
                      HingeJoint {
                        jointParameters HingeJointParameters {
                          position -2.4208978598603183e-05
                          axis -4e-06 6e-06 -1
                          anchor 0 0.2 0
                        }
                        device [
                          RotationalMotor {
                            name "Joint-24"
                            maxTorque 10000
                          }
                          PositionSensor {
                            name "Joint-24_sensor"
                          }
                        ]
                        endPoint Solid {
                          translation 0 0.2 0
                          rotation 0.9662954620692797 0.25743558414352363 -9.999613823609646e-07 3.141600000031971
                          children [
                            Shape {
                              appearance USE mat
                              geometry DEF Link-24 Mesh {
                                url [
                                  "C:/Users/andyf/PycharmProjects/Pytorch_with_webots/protos/robots/FirstTry0314/meshes/Link-24.STL"
                                ]
                              }
                            }
                          ]
                          name "Link-24"
                          boundingObject USE Link-24
                          physics Physics {
                            density -1
                            mass 1.3182
                            centerOfMass [
                              0.047942 0.21275 0.00054
                            ]
                            inertiaMatrix [
                              0.028713 0.00066838 0.028833
                              -0.00057712 3.2444e-05 0.00015134
                            ]
                          }
                        }
                      }
                    ]
                    name "Link-23"
                    boundingObject USE Link-23
                    physics Physics {
                      density -1
                      mass 0.49632
                      centerOfMass [
                        0 0.1 0.002867
                      ]
                      inertiaMatrix [
                        0.0019227 0.00020011 0.0019242
                        1.527e-18 -2.7105e-20 1.6348e-18
                      ]
                    }
                  }
                }
              ]
              name "Link-22"
              boundingObject USE Link-22
              physics Physics {
                density -1
                mass 0.12291
                centerOfMass [
                  -0.005788 -0.036099 0.004011
                ]
                inertiaMatrix [
                  7.6838e-05 7.1867e-05 4.7075e-05
                  -4.075e-07 1.327e-05 2.8244e-07
                ]
              }
            }
          }
        ]
        name "Link-21"
        boundingObject USE Link-21
        physics Physics {
          density -1
          mass 0.13426
          centerOfMass [
            0.000524 -0.048741 0
          ]
          inertiaMatrix [
            5.9611e-05 5.5476e-05 6.1772e-05
            8.862e-08 1.6941e-21 1.4029e-21
          ]
        }
      }
    }
    HingeJoint {
      jointParameters HingeJointParameters {
        position -3.299073093698159e-05
        axis -1 -4e-06 0
        anchor 0.091803 0.05 0.012279
      }
      device [
        RotationalMotor {
          name "Joint-31"
          maxTorque 10000
        }
        PositionSensor {
          name "Joint-31_sensor"
        }
      ]
      endPoint Solid {
        translation 0.091803 0.05 0.012279
        rotation 0.5694045602741301 -0.5694025602532774 0.5929242541134889 2.0711957848884692
        children [
          Shape {
            appearance USE mat
            geometry DEF Link-31 Mesh {
              url [
                "C:/Users/andyf/PycharmProjects/Pytorch_with_webots/protos/robots/FirstTry0314/meshes/Link-31.STL"
              ]
            }
          }
          HingeJoint {
            jointParameters HingeJointParameters {
              position -1.4478237976502012e-05
              axis -1 -4e-06 0
              anchor 0.037602 -0.05 0
            }
            device [
              RotationalMotor {
                name "Joint-32"
                maxTorque 10000
              }
              PositionSensor {
                name "Joint-32_sensor"
              }
            ]
            endPoint Solid {
              translation 0.037602 -0.05 0
              rotation 0.5616023359460591 -0.5616003359329317 0.6076247846656258 2.0495821309579325
              children [
                Shape {
                  appearance USE mat
                  geometry DEF Link-32 Mesh {
                    url [
                      "C:/Users/andyf/PycharmProjects/Pytorch_with_webots/protos/robots/FirstTry0314/meshes/Link-32.STL"
                    ]
                  }
                }
                HingeJoint {
                  jointParameters HingeJointParameters {
                    position 5.285846074141576e-05
                    axis 1 7e-06 -1e-06
                    anchor 0 -0.037398 0.025
                  }
                  device [
                    RotationalMotor {
                      name "Joint-33"
                      maxTorque 10000
                    }
                    PositionSensor {
                      name "Joint-33_sensor"
                    }
                  ]
                  endPoint Solid {
                    translation 0 -0.037398 0.025
                    rotation 0.7038955397622396 0.0951952645370235 0.7038955396310957 2.9517842067992186
                    children [
                      Shape {
                        appearance USE mat
                        geometry DEF Link-33 Mesh {
                          url [
                            "C:/Users/andyf/PycharmProjects/Pytorch_with_webots/protos/robots/FirstTry0314/meshes/Link-33.STL"
                          ]
                        }
                      }
                      HingeJoint {
                        jointParameters HingeJointParameters {
                          position -4.01269757947988e-05
                          axis 3e-06 -7e-06 -1
                          anchor 0 0.2 0
                        }
                        device [
                          RotationalMotor {
                            name "Joint-34"
                            maxTorque 10000
                          }
                          PositionSensor {
                            name "Joint-34_sensor"
                          }
                        ]
                        endPoint Solid {
                          translation 0 0.2 0
                          rotation -0.981586390466384 -0.19101873743215833 -9.999245688684027e-07 3.1416000000243867
                          children [
                            Shape {
                              appearance USE mat
                              geometry DEF Link-34 Mesh {
                                url [
                                  "C:/Users/andyf/PycharmProjects/Pytorch_with_webots/protos/robots/FirstTry0314/meshes/Link-34.STL"
                                ]
                              }
                            }
                          ]
                          name "Link-34"
                          boundingObject USE Link-34
                          physics Physics {
                            density -1
                            mass 1.3182
                            centerOfMass [
                              0.047942 0.21275 0.00054
                            ]
                            inertiaMatrix [
                              0.028713 0.00066838 0.028833
                              -0.00057712 3.2444e-05 0.00015134
                            ]
                          }
                        }
                      }
                    ]
                    name "Link-33"
                    boundingObject USE Link-33
                    physics Physics {
                      density -1
                      mass 0.49632
                      centerOfMass [
                        0 0.1 0.002867
                      ]
                      inertiaMatrix [
                        0.0019227 0.00020011 0.0019242
                        -1.9327e-18 5.421e-20 -2.8376e-19
                      ]
                    }
                  }
                }
              ]
              name "Link-32"
              boundingObject USE Link-32
              physics Physics {
                density -1
                mass 0.12291
                centerOfMass [
                  -0.005788 -0.036825 0.004011
                ]
                inertiaMatrix [
                  7.6838e-05 7.1867e-05 4.7075e-05
                  -4.075e-07 1.327e-05 2.8244e-07
                ]
              }
            }
          }
        ]
        name "Link-31"
        boundingObject USE Link-31
        physics Physics {
          density -1
          mass 0.13426
          centerOfMass [
            0.000524 -0.048741 0
          ]
          inertiaMatrix [
            5.9611e-05 5.5476e-05 6.1772e-05
            8.862e-08 -5.294e-21 2.3868e-21
          ]
        }
      }
    }
    HingeJoint {
      jointParameters HingeJointParameters {
        position 6.118108765301848e-05
        axis 1 1.1e-05 -1e-06
        anchor -0.1082 0.05 0.012279
      }
      device [
        RotationalMotor {
          name "Joint-41"
          maxTorque 10000
        }
        PositionSensor {
          name "Joint-41_sensor"
        }
      ]
      endPoint Solid {
        translation -0.1082 0.05 0.012279
        rotation 0.6000500773566021 0.6000560772273559 0.5290298751931249 4.114804712404651
        children [
          Shape {
            appearance USE mat
            geometry DEF Link-41 Mesh {
              url [
                "C:/Users/andyf/PycharmProjects/Pytorch_with_webots/protos/robots/FirstTry0314/meshes/Link-41.STL"
              ]
            }
          }
          HingeJoint {
            jointParameters HingeJointParameters {
              position -1.3956263987045092e-05
              axis -1 -4e-06 0
              anchor 0.038483 -0.05 0
            }
            device [
              RotationalMotor {
                name "Joint-42"
                maxTorque 10000
              }
              PositionSensor {
                name "Joint-42_sensor"
              }
            ]
            endPoint Solid {
              translation 0.038483 -0.05 0
              rotation 0.5844169318092832 -0.5844149317972113 0.5629529618956497 2.116129156226291
              children [
                Shape {
                  appearance USE mat
                  geometry DEF Link-42 Mesh {
                    url [
                      "C:/Users/andyf/PycharmProjects/Pytorch_with_webots/protos/robots/FirstTry0314/meshes/Link-42.STL"
                    ]
                  }
                }
                HingeJoint {
                  jointParameters HingeJointParameters {
                    position -3.947430589807509e-06
                    axis 1 7e-06 -1e-06
                    anchor 0 -0.036517 0.025
                  }
                  device [
                    RotationalMotor {
                      name "Joint-43"
                      maxTorque 10000
                    }
                    PositionSensor {
                      name "Joint-43_sensor"
                    }
                  ]
                  endPoint Solid {
                    translation 0 -0.036517 0.025
                    rotation 0.7049404395849156 0.0782173463006517 0.7049404395943744 2.9854862172970114
                    children [
                      Shape {
                        appearance USE mat
                        geometry DEF Link-43 Mesh {
                          url [
                            "C:/Users/andyf/PycharmProjects/Pytorch_with_webots/protos/robots/FirstTry0314/meshes/Link-43.STL"
                          ]
                        }
                      }
                      HingeJoint {
                        jointParameters HingeJointParameters {
                          position 5.022824139754418e-06
                          axis 3e-06 -7e-06 -1
                          anchor 0 0.2 0
                        }
                        device [
                          RotationalMotor {
                            name "Joint-44"
                            maxTorque 10000
                          }
                          PositionSensor {
                            name "Joint-44_sensor"
                          }
                        ]
                        endPoint Solid {
                          translation 0 0.2 0
                          rotation -0.9722547421474053 -0.233924595480857 -1.0000097887195605e-06 3.141599999998597
                          children [
                            Shape {
                              appearance USE mat
                              geometry DEF Link-44 Mesh {
                                url [
                                  "C:/Users/andyf/PycharmProjects/Pytorch_with_webots/protos/robots/FirstTry0314/meshes/Link-44.STL"
                                ]
                              }
                            }
                          ]
                          name "Link-44"
                          boundingObject USE Link-44
                          physics Physics {
                            density -1
                            mass 1.3182
                            centerOfMass [
                              0.047942 0.21275 0.00054
                            ]
                            inertiaMatrix [
                              0.028713 0.00066838 0.028833
                              -0.00057712 3.2444e-05 0.00015134
                            ]
                          }
                        }
                      }
                    ]
                    name "Link-43"
                    boundingObject USE Link-43
                    physics Physics {
                      density -1
                      mass 0.49632
                      centerOfMass [
                        0 0.1 0.002867
                      ]
                      inertiaMatrix [
                        0.0019227 0.00020011 0.0019242
                        1.3239e-18 2.7105e-20 -4.3707e-19
                      ]
                    }
                  }
                }
              ]
              name "Link-42"
              boundingObject USE Link-42
              physics Physics {
                density -1
                mass 0.12291
                centerOfMass [
                  -0.005788 -0.035945 0.004011
                ]
                inertiaMatrix [
                  7.6838e-05 7.1867e-05 4.7075e-05
                  -4.075e-07 1.327e-05 2.8244e-07
                ]
              }
            }
          }
        ]
        name "Link-41"
        boundingObject USE Link-41
        physics Physics {
          density -1
          mass 0.13426
          centerOfMass [
            0.000524 -0.048741 0
          ]
          inertiaMatrix [
            5.9611e-05 5.5476e-05 6.1772e-05
            8.862e-08 0 1.4261e-21
          ]
        }
      }
    }
  ]
  name "FirstTry0314"
  boundingObject USE base_link
  physics Physics {
    density -1
    mass 1.3313
    centerOfMass [
      -0.008197 -0.00733 0.1
    ]
    inertiaMatrix [
      0.020645 0.023213 0.0034844
      -3.7461e-19 -2.6999e-20 1.2187e-18
    ]
  }
  controller "<extern>"
  supervisor TRUE
}
