#VRML_SIM R2023b utf8

EXTERNPROTO "https://raw.githubusercontent.com/cyberbotics/webots/R2023b/projects/objects/backgrounds/protos/TexturedBackground.proto"
EXTERNPROTO "https://raw.githubusercontent.com/cyberbotics/webots/R2023b/projects/objects/backgrounds/protos/TexturedBackgroundLight.proto"
EXTERNPROTO "https://raw.githubusercontent.com/cyberbotics/webots/R2023b/projects/objects/floors/protos/RectangleArena.proto"

WorldInfo {
}
Viewpoint {
  orientation -0.16545917684627512 0.40988828475956346 0.8970032635471379 0.7347216318391719
  position -8.66796669656863 -7.278939308391884 4.048357075185639
}
TexturedBackground {
}
TexturedBackgroundLight {
}
RectangleArena {
  floorSize 20 20
  floorTileSize 20 20
}
DEF Severus_node Robot {
  children [
    Shape {
      appearance DEF base_link_material PBRAppearance {
        baseColor 0.792157 0.819608 0.933333
        roughness 1
        metalness 0
      }
      geometry DEF base_link Mesh {
        url [
          "C:/Users/andyf/PycharmProjects/Pytorch_with_webots/protos/robots/Severus/meshes/base_link.STL"
        ]
      }
    }
    HingeJoint {
      jointParameters HingeJointParameters {
        axis 0 -4e-06 1
        anchor 0 0 0.01
      }
      device [
        RotationalMotor {
          name "Joint_11"
          maxTorque 10000
        }
        PositionSensor {
          name "Joint_11_sensor"
        }
      ]
      endPoint Solid {
        translation 0 0 0.01
        rotation 1 0 0 1.5708
        children [
          Shape {
            appearance DEF Link_11_material PBRAppearance {
              baseColor 0.792157 0.819608 0.933333
              roughness 1
              metalness 0
            }
            geometry DEF Link_11 Mesh {
              url [
                "C:/Users/andyf/PycharmProjects/Pytorch_with_webots/protos/robots/Severus/meshes/Link_11.STL"
              ]
            }
          }
          HingeJoint {
            jointParameters HingeJointParameters {
              anchor 0 0.03 0
            }
            device [
              RotationalMotor {
                name "Joint_12"
                maxTorque 10000
              }
              PositionSensor {
                name "Joint_12_sensor"
              }
            ]
            endPoint Solid {
              translation 0 0.03 0
              children [
                Shape {
                  appearance DEF Link_12_material PBRAppearance {
                    baseColor 0.792157 0.819608 0.933333
                    roughness 1
                    metalness 0
                  }
                  geometry DEF Link_12 Mesh {
                    url [
                      "C:/Users/andyf/PycharmProjects/Pytorch_with_webots/protos/robots/Severus/meshes/Link_12.STL"
                    ]
                  }
                }
                HingeJoint {
                  jointParameters HingeJointParameters {
                    anchor 0 0.17 -0.04
                  }
                  device [
                    RotationalMotor {
                      name "Joint_13"
                      maxTorque 10000
                    }
                    PositionSensor {
                      name "Joint_13_sensor"
                    }
                  ]
                  endPoint Solid {
                    translation 0 0.17 -0.04
                    rotation 1 0 0 3.1416
                    children [
                      Shape {
                        appearance DEF Link_13_material PBRAppearance {
                          baseColor 0.792157 0.819608 0.933333
                          roughness 1
                          metalness 0
                        }
                        geometry DEF Link_13 Mesh {
                          url [
                            "C:/Users/andyf/PycharmProjects/Pytorch_with_webots/protos/robots/Severus/meshes/Link_13.STL"
                          ]
                        }
                      }
                      HingeJoint {
                        jointParameters HingeJointParameters {
                          anchor 0 -0.17 0
                        }
                        device [
                          RotationalMotor {
                            name "Joint_14"
                            maxTorque 10000
                          }
                          PositionSensor {
                            name "Joint_14_sensor"
                          }
                        ]
                        endPoint Solid {
                          translation 0 -0.17 0
                          children [
                            Shape {
                              appearance DEF Link_14_material PBRAppearance {
                                baseColor 0.792157 0.819608 0.933333
                                roughness 1
                                metalness 0
                              }
                              geometry DEF Link_14 Mesh {
                                url [
                                  "C:/Users/andyf/PycharmProjects/Pytorch_with_webots/protos/robots/Severus/meshes/Link_14.STL"
                                ]
                              }
                            }
                          ]
                          name "Link_14"
                          boundingObject USE Link_14
                          physics Physics {
                            density -1
                            mass 0.111659
                            centerOfMass [
                              0.000961 -0.028237 0
                            ]
                            inertiaMatrix [
                              0.0001375842 0.0002517977 0.0001375806
                              -2.606804e-06 1.139915e-23 -4.027199e-21
                            ]
                          }
                        }
                      }
                    ]
                    name "Link_13"
                    boundingObject USE Link_13
                    physics Physics {
                      density -1
                      mass 0.073603
                      centerOfMass [
                        -0.002915 -0.085 0
                      ]
                      inertiaMatrix [
                        0.0002742236 1.321639e-05 0.0002767972
                        9.760957e-21 3.279274e-21 -1.406207e-20
                      ]
                    }
                  }
                }
              ]
              name "Link_12"
              boundingObject USE Link_12
              physics Physics {
                density -1
                mass 0.091103
                centerOfMass [
                  0.002355 0.102741 -0.006869
                ]
                inertiaMatrix [
                  0.0004111 3.259913e-05 0.0003986976
                  3.383938e-06 2.394956e-06 4.20131e-05
                ]
              }
            }
          }
        ]
        name "Link_11"
        boundingObject USE Link_11
        physics Physics {
          density -1
          mass 0.019685
          centerOfMass [
            -0.005449 0.020765 0
          ]
          inertiaMatrix [
            4.099907e-06 2.161216e-06 3.61486e-06
            5.687175e-07 3.820046e-24 -3.37216e-22
          ]
        }
      }
    }
  ]
  name "Severus"
  boundingObject USE base_link
  physics Physics {
    density -1
    mass 0.089241
    centerOfMass [
      0 0.00255 0
    ]
    inertiaMatrix [
      0.0001244727 0.0002485297 0.0001244727
      0 0 -4.135903e-22
    ]
  }
  controller "<extern>"
  supervisor TRUE
}
